<robot
  name="svenzva_description">
  <link
    name="base_link">
    <inertial>
      <origin
        xyz="0.00534105939021147 -0.00206629541945739 0.0284371004255722"
        rpy="0 0 0" />
      <mass
        value="0.506214468139727" />
      <inertia
        ixx="0.00114305339332644"
        ixy="3.15672381992316E-05"
        ixz="-5.92611471736903E-06"
        iyy="0.00117822681147312"
        iyz="-2.22879533478747E-06"
        izz="0.00169367351719374" />
    </inertial>
    <visual>
      <origin
        xyz="0 0 0"
        rpy="0 0 0" />
      <geometry>
        <mesh
          filename="package://svenzva_description/meshes/base_link.STL" />
      </geometry>
      <material
        name="">
        <color
          rgba="0.3 0.3 0.3 1" />
      </material>
    </visual>
    <collision>
      <origin
        xyz="0 0 0"
        rpy="0 0 0" />
      <geometry>
        <mesh
          filename="package://svenzva_description/meshes/base_link.STL" />
      </geometry>
    </collision>
  </link>
  <link
    name="link_1">
    <inertial>
      <origin
        xyz="0.00607508557819933 -2.20815694732225E-05 0.0577282570202576"
        rpy="0 0 0" />
      <mass
        value="0.153541664031025" />
      <inertia
        ixx="0.000143859857634591"
        ixy="2.3744760815064E-08"
        ixz="-1.48862872082739E-05"
        iyy="0.000169533549591294"
        iyz="-1.75052266297562E-07"
        izz="5.71468876958754E-05" />
    </inertial>
    <visual>
      <origin
        xyz="0 0 0"
        rpy="0 0 0" />
      <geometry>
        <mesh
          filename="package://svenzva_description/meshes/link_1.STL" />
      </geometry>
      <material
        name="">
        <color
          rgba="0.792156862745098 0.819607843137255 0.933333333333333 1" />
      </material>
    </visual>
    <collision>
      <origin
        xyz="0 0 0"
        rpy="0 0 0" />
      <geometry>
        <mesh
          filename="package://svenzva_description/meshes/link_1.STL" />
      </geometry>
    </collision>
  </link>
  <joint
    name="joint_1"
    type="revolute">
    <limit effort="30" velocity="1.0" lower="0" upper="6.0" />
    <origin
      xyz="0 0 0.07119999984"
      rpy="-1.93033535706571E-16 -1.54074395550979E-32 0" />
    <parent
      link="base_link" />
    <child
      link="link_1" />
    <axis
      xyz="0 0 -1" />
  </joint>
  <link
    name="link_2">
    <inertial>
      <origin
        xyz="1.07182976154903E-06 0.103154493257645 0.0141451712274321"
        rpy="0 0 0" />
      <mass
        value="0.281175487770198" />
      <inertia
        ixx="0.00215619450264231"
        ixy="-1.18560079052635E-08"
        ixz="-3.46566000959967E-09"
        iyy="0.000122217546884776"
        iyz="0.0001531208460593"
        izz="0.00212480482551255" />
    </inertial>
    <visual>
      <origin
        xyz="0 0 0"
        rpy="0 0 0" />
      <geometry>
        <mesh
          filename="package://svenzva_description/meshes/link_2.STL" />
      </geometry>
      <material
        name="">
        <color
          rgba="0.898039215686275 0.917647058823529 0.929411764705882 1" />
      </material>
    </visual>
    <collision>
      <origin
        xyz="0 0 0"
        rpy="0 0 0" />
      <geometry>
        <mesh
          filename="package://svenzva_description/meshes/link_2.STL" />
      </geometry>
    </collision>
  </link>
  <joint
    name="joint_2"
    type="revolute">
    <limit effort="30" velocity="1.0" lower="-2.0" upper="2.0" />
    <origin
      xyz="0.00891249579997938 0 0.09644999999"
      rpy="1.5707963267949 -1.93033535706571E-16 1.5707963267949" />
    <parent
      link="link_1" />
    <child
      link="link_2" />
    <axis
      xyz="0 0 -1" />
  </joint>
  <link
    name="link_3">
    <inertial>
      <origin
        xyz="-0.00158295343768384 0.0592398990299627 0.0120000556558225"
        rpy="0 0 0" />
      <mass
        value="0.246165133529195" />
      <inertia
        ixx="0.000741437282012257"
        ixy="1.95254756418241E-05"
        ixz="-2.40700471861297E-06"
        iyy="0.000126868927384053"
        iyz="9.02514597868819E-05"
        izz="0.000753110375891627" />
    </inertial>
    <visual>
      <origin
        xyz="0 0 0"
        rpy="0 0 0" />
      <geometry>
        <mesh
          filename="package://svenzva_description/meshes/link_3.STL" />
      </geometry>
      <material
        name="">
        <color
          rgba="0.898039215686275 0.917647058823529 0.929411764705882 1" />
      </material>
    </visual>
    <collision>
      <origin
        xyz="0 0 0"
        rpy="0 0 0" />
      <geometry>
        <mesh
          filename="package://svenzva_description/meshes/link_3.STL" />
      </geometry>
    </collision>
  </link>
  <joint
    name="joint_3"
    type="revolute">
    <limit effort="30" velocity="1.0" lower="-2.0" upper="2.0" />
    <origin
      xyz="0 0.22770179999 0.00317500840002059"
      rpy="-3.14159265358979 -2.14461300673676E-15 3.14159265358979" />
    <parent
      link="link_2" />
    <child
      link="link_3" />
    <axis
      xyz="0 0 -1" />
  </joint>
  <link
    name="link_4">
    <inertial>
      <origin
        xyz="0.00183872739831845 0.0797738010820961 -0.00643156916623339"
        rpy="0 0 0" />
      <mass
        value="0.211922628762084" />
      <inertia
        ixx="0.000691521163409683"
        ixy="-1.6472855114629E-05"
        ixz="-1.88349270867275E-06"
        iyy="0.000150807902737057"
        iyz="-8.19166968109381E-05"
        izz="0.000636626532287155" />
    </inertial>
    <visual>
      <origin
        xyz="0 0 0"
        rpy="0 0 0" />
      <geometry>
        <mesh
          filename="package://svenzva_description/meshes/link_4.STL" />
      </geometry>
      <material
        name="">
        <color
          rgba="0.898039215686275 0.917647058823529 0.929411764705882 1" />
      </material>
    </visual>
    <collision>
      <origin
        xyz="0 0 0"
        rpy="0 0 0" />
      <geometry>
        <mesh
          filename="package://svenzva_description/meshes/link_4.STL" />
      </geometry>
    </collision>
  </link>
  <joint
    name="joint_4"
    type="revolute">
    <limit effort="30" velocity="1.0" lower="-2.4" upper="2.4" />
    <origin
      xyz="-0.00165000009395299 0.13769999999 0.00581250408200003"
      rpy="0 1.5707963267949 0" />
    <parent
      link="link_3" />
    <child
      link="link_4" />
    <axis
      xyz="0 0 1" />
  </joint>
  <link
    name="link_5">
    <inertial>
      <origin
        xyz="0.000198138937290779 0.0317576969029498 0.00758259926210232"
        rpy="0 0 0" />
      <mass
        value="0.164460903684414" />
      <inertia
        ixx="0.000179026236386024"
        ixy="1.25477268152759E-07"
        ixz="1.92814341999761E-07"
        iyy="0.000130748756855599"
        iyz="3.21489367850694E-05"
        izz="0.00014102690064648" />
    </inertial>
    <visual>
      <origin
        xyz="0 0 0"
        rpy="0 0 0" />
      <geometry>
        <mesh
          filename="package://svenzva_description/meshes/link_5.STL" />
      </geometry>
      <material
        name="">
        <color
          rgba="0.898039215686275 0.917647058823529 0.929411764705882 1" />
      </material>
    </visual>
    <collision>
      <origin
        xyz="0 0 0"
        rpy="0 0 0" />
      <geometry>
        <mesh
          filename="package://svenzva_description/meshes/link_5.STL" />
      </geometry>
    </collision>
  </link>
  <joint
    name="joint_5"
    type="revolute">
    <limit effort="30" velocity="1.0" lower="-1.9" upper="1.9" />
    <origin
      xyz="0.00165000009004705 0.15039999999 -0.00158749994695297"
      rpy="0 1.5707963267949 0" />
    <parent
      link="link_4" />
    <child
      link="link_5" />
    <axis
      xyz="0 0 -1" />
  </joint>
  <link
    name="link_6">
    <inertial>
      <origin
        xyz="-0.0057601102835214 2.01339142936168E-05 -0.0374605011648069"
        rpy="0 0 0" />
      <mass
        value="0.195112141464075" />
      <inertia
        ixx="0.000124406751238452"
        ixy="-3.20472092584313E-06"
        ixz="7.06955362871711E-06"
        iyy="0.000245991583429068"
        iyz="-1.02047290359859E-08"
        izz="0.000219444070727294" />
    </inertial>
    <visual>
      <origin
        xyz="0 0 0"
        rpy="0 0 0" />
      <geometry>
        <mesh
          filename="package://svenzva_description/meshes/link_6.STL" />
      </geometry>
      <material
        name="">
        <color
          rgba="0.3 0.3 0.3 1" />
      </material>
    </visual>
    <collision>
      <origin
        xyz="0 0 0"
        rpy="0 0 0" />
      <geometry>
        <mesh
          filename="package://svenzva_description/meshes/link_6.STL" />
      </geometry>
    </collision>
  </link>
  <joint
    name="joint_6"
    type="revolute">
    <limit effort="30" velocity="1.0" lower="0.0" upper="6.0" />
    <origin
      xyz="-0.0147500000020004 0.0754999999999999 0.00142499999999982"
      rpy="1.5707963267949 1.5707963267949 0" />
    <parent
      link="link_5" />
    <child
      link="link_6" />
    <axis
      xyz="0 0 -1" />
  </joint>
  <link
    name="link_7">
    <inertial>
      <origin
        xyz="-0.000635000130040961 1.72150542085414E-10 0.0213790033648974"
        rpy="0 0 0" />
      <mass
        value="0.0354585256038568" />
      <inertia
        ixx="2.02110056282734E-05"
        ixy="4.52582961569063E-06"
        ixz="-3.28017662692727E-14"
        iyy="1.66232577520863E-05"
        iyz="6.19440107025139E-14"
        izz="1.97134164501418E-05" />
    </inertial>
    <visual>
      <origin
        xyz="0 0 0"
        rpy="0 0 0" />
      <geometry>
        <mesh
          filename="package://svenzva_description/meshes/link_7.STL" />
      </geometry>
      <material
        name="">
        <color
          rgba="0.3 0.3 0.3 1" />
      </material>
    </visual>
    <collision>
      <origin
        xyz="0 0 0"
        rpy="0 0 0" />
      <geometry>
        <mesh
          filename="package://svenzva_description/meshes/link_7.STL" />
      </geometry>
    </collision>
  </link>
  <joint
    name="joint_7"
    type="fixed">
    <limit lower="-0.05" upper="0.05" velocity="1.0" effort="5"/>
    <origin
      xyz="0 0 -0.0573569998840002"
      rpy="-3.14159265358979 0 -3.14159265358979" />
    <parent
      link="link_6" />
    <child
      link="link_7" />
    <axis
      xyz="-1 0 0" />
  </joint>
  <link name="ee_link"> </link>
  <joint name="ee_joint" type="fixed">
    <parent link="link_7"/>
    <child link="ee_link"/>
    <origin xyz="0 0 0.0"/>
  </joint>

</robot>
