<?xml version="1.0" ?>
<!-- =================================================================================== -->
<!-- |    This document was autogenerated by xacro from ../robots/svenzva_arm.xacro    | -->
<!-- |    EDITING THIS FILE BY HAND IS NOT RECOMMENDED                                 | -->
<!-- =================================================================================== -->
<robot name="revel" xmlns:xacro="http://ros.org/wiki/xacro">
  <!-- Set link name properties -->
  <gazebo>
    <plugin filename="libgazebo_ros_control.so" name="gazebo_ros_control">
      <robotNamespace>/revel/</robotNamespace>
    </plugin>
  </gazebo>
  <link name="world"/>
  <link name="base_link">
    <inertial>
      <origin rpy="0 0 0" xyz="0.00316788473984359 0.00144654213217675 0.0163503481531875"/>
      <mass value="0.673945611735726"/>
      <inertia ixx="0.00108417285375602" ixy="-1.8840422640439E-05" ixz="-2.77034436629817E-05" iyy="0.00110167255395701" iyz="-9.55407578935953E-06" izz="0.00176149660426914"/>
    </inertial>
    <visual>
      <origin rpy="0 0 0" xyz="0 0 0"/>
      <geometry>
        <mesh filename="package://svenzva_description/textures/base_link.dae"/>
      </geometry>
      <material name="">
        <color rgba="0.250980392156863 0.250980392156863 0.250980392156863 1"/>
      </material>
    </visual>
    <collision>
      <origin rpy="0 0 0" xyz="0 0 0"/>
      <geometry>
        <mesh filename="package://svenzva_description/meshes/base_link.STL"/>
      </geometry>
    </collision>
  </link>
  <joint name="world_joint" type="fixed">
    <parent link="world"/>
    <child link="base_link"/>
  </joint>
  <link name="link_1">
    <inertial>
      <origin rpy="0 0 0" xyz="0.000394740619310651 -0.00394697747318002 0.0453185973462504"/>
      <mass value="0.386092665970672"/>
      <inertia ixx="0.000907442488265593" ixy="9.91871224876259E-09" ixz="-3.6939781644972E-08" iyy="0.000855772900574106" iyz="9.21169325994586E-05" izz="0.000187120993266731"/>
    </inertial>
    <visual>
      <origin rpy="0 0 0" xyz="0 0 0"/>
      <geometry>
        <mesh filename="package://svenzva_description/textures/link_1.dae"/>
      </geometry>
      <material name="">
        <color rgba="0.898039215686275 0.917647058823529 0.929411764705882 1"/>
      </material>
    </visual>
    <collision>
      <origin rpy="0 0 0" xyz="0 0 0"/>
      <geometry>
        <mesh filename="package://svenzva_description/meshes/link_1.STL"/>
      </geometry>
    </collision>
  </link>
  <joint name="joint_1" type="revolute">
    <origin rpy="0 0 0" xyz="0 0 0.064752"/>
    <parent link="base_link"/>
    <child link="link_1"/>
    <axis xyz="0 0 -1"/>
    <limit effort="10" lower="-3.14" upper="3.14" velocity="1"/>
  </joint>
  <link name="link_2">
    <inertial>
      <origin rpy="0 0 0" xyz="-4.6967E-05 0.11408 0.016011"/>
      <mass value="0.63194"/>
      <inertia ixx="0.0063243" ixy="2.8676E-06" ixz="-5.7924E-07" iyy="0.00040505" iyz="0.00027822" izz="0.0061896"/>
    </inertial>
    <visual>
      <origin rpy="0 0 0" xyz="0 0 0"/>
      <geometry>
        <mesh filename="package://svenzva_description/textures/link_2.dae"/>
      </geometry>
      <material name="">
        <color rgba="0.89804 0.91765 0.92941 1"/>
      </material>
    </visual>
    <collision>
      <origin rpy="0 0 0" xyz="0 0 0"/>
      <geometry>
        <mesh filename="package://svenzva_description/meshes/link_2.STL"/>
      </geometry>
    </collision>
  </link>
  <joint name="joint_2" type="revolute">
    <origin rpy="1.5708 0 0" xyz="0.00039444 -0.0064686 0.11076"/>
    <parent link="link_1"/>
    <child link="link_2"/>
    <axis xyz="0 0 -1"/>
    <limit effort="10" lower="-1.5" upper="1.5" velocity="1"/>
  </joint>
  <link name="link_3">
    <inertial>
      <origin rpy="0 0 0" xyz="-2.1274E-06 0.051237 -0.015758"/>
      <mass value="0.37014"/>
      <inertia ixx="0.0012648" ixy="3.174E-08" ixz="2.0627E-08" iyy="0.00028079" iyz="-0.00016675" izz="0.0011912"/>
    </inertial>
    <visual>
      <origin rpy="0 0 0" xyz="0 0 0"/>
      <geometry>
        <mesh filename="package://svenzva_description/textures/link_3.dae"/>
      </geometry>
      <material name="">
        <color rgba="0.89804 0.91765 0.92941 1"/>
      </material>
    </visual>
    <collision>
      <origin rpy="0 0 0" xyz="0 0 0"/>
      <geometry>
        <mesh filename="package://svenzva_description/meshes/link_3.STL"/>
      </geometry>
    </collision>
  </link>
  <joint name="joint_3" type="revolute">
    <origin rpy="0 0 0" xyz="0 0.26625 0.014294"/>
    <parent link="link_2"/>
    <child link="link_3"/>
    <axis xyz="0 0 1"/>
    <limit effort="10" lower="-2.5" upper="2.5" velocity="1"/>
  </joint>
  <link name="link_4">
    <inertial>
      <origin rpy="0 0 0" xyz="-3.78177057922539E-05 -0.00364125420498501 0.0447609638463843"/>
      <mass value="0.208577727676899"/>
      <inertia ixx="0.000277065539345918" ixy="1.68532231246742E-08" ixz="-2.40655665815155E-07" iyy="0.000239397752113429" iyz="1.85199498298306E-05" izz="8.5137482896374E-05"/>
    </inertial>
    <visual>
      <origin rpy="0 0 0" xyz="0 0 0"/>
      <geometry>
        <mesh filename="package://svenzva_description/textures/link_4.dae"/>
      </geometry>
      <material name="">
        <color rgba="0.898039215686275 0.917647058823529 0.929411764705882 1"/>
      </material>
    </visual>
    <collision>
      <origin rpy="0 0 0" xyz="0 0 0"/>
      <geometry>
        <mesh filename="package://svenzva_description/meshes/link_4.STL"/>
      </geometry>
    </collision>
  </link>
  <joint name="joint_4" type="revolute">
    <origin rpy="-1.5708 0 0" xyz="0 0.13713 -0.015019"/>
    <parent link="link_3"/>
    <child link="link_4"/>
    <axis xyz="0 0 -1"/>
    <limit effort="10" lower="-4.5" upper="2.5" velocity="1"/>
  </joint>
  <link name="link_5">
    <inertial>
      <origin rpy="0 0 0" xyz="-4.10966793018292E-06 -0.0119844325813299 0.0254510287985342"/>
      <mass value="0.198143515414093"/>
      <inertia ixx="0.000254862990258315" ixy="-7.36847584764268E-09" ixz="-2.04155550591897E-08" iyy="0.000174493924598589" iyz="-4.40919139889134E-05" izz="0.000127265974156123"/>
    </inertial>
    <visual>
      <origin rpy="0 0 0" xyz="0 0 0"/>
      <geometry>
        <mesh filename="package://svenzva_description/textures/link_5.dae"/>
      </geometry>
      <material name="">
        <color rgba="0.529411764705882 0.549019607843137 0.549019607843137 1"/>
      </material>
    </visual>
    <collision>
      <origin rpy="0 0 0" xyz="0 0 0"/>
      <geometry>
        <mesh filename="package://svenzva_description/meshes/link_5.STL"/>
      </geometry>
    </collision>
  </link>
  <joint name="joint_5" type="revolute">
    <origin rpy="0 0 0" xyz="0 -0.0040438 0.086925"/>
    <parent link="link_4"/>
    <child link="link_5"/>
    <axis xyz="0 1 0"/>
    <limit effort="10" lower="-1.8" upper="1.8" velocity="1"/>
  </joint>
  <link name="link_6">
    <inertial>
      <origin rpy="0 0 3.14159" xyz="1.70870985564525E-05 0.00518372417730809 -0.0301873871981205"/>
      <mass value="0.217466355310719"/>
      <inertia ixx="0.000283317945614306" ixy="4.01931843139719E-06" ixz="2.01137426532614E-08" iyy="0.000144510928899331" iyz="-1.12427876997159E-05" izz="0.000246869181878746"/>
    </inertial>
    <visual>
      <origin rpy="0 0 3.14159" xyz="0 0 0"/>
      <geometry>
        <mesh filename="package://svenzva_description/textures/link_6.dae"/>
      </geometry>
      <material name="">
        <color rgba="0.752941176470588 0.752941176470588 0.752941176470588 1"/>
      </material>
    </visual>
    <collision>
      <origin rpy="0 0 0" xyz="0 0 0"/>
      <geometry>
        <mesh filename="package://svenzva_description/meshes/link_6.STL"/>
      </geometry>
    </collision>
  </link>
  <joint name="joint_6" type="revolute">
    <origin rpy="3.1416 0 3.1416" xyz="0 -0.019119 0.082"/>
    <parent link="link_5"/>
    <child link="link_6"/>
    <axis xyz="0 0 -1"/>
    <limit effort="10" lower="0.2" upper="5.5" velocity="1"/>
  </joint>
  <link name="finger_link_1">
    <inertial>
      <origin rpy="0 0 1.570796" xyz="0 0 -0.003175"/>
      <mass value="0.0220307791071739"/>
      <inertia ixx="9.08331950596468E-06" ixy="-2.05394082888464E-06" ixz="-2.23772944669454E-06" iyy="1.04239718244321E-05" iyz="-2.75990314800171E-06" izz="9.60841591398502E-06"/>
    </inertial>
    <visual>
      <origin rpy="0 0 1.570796" xyz="0 0 -0.003175"/>
      <geometry>
        <mesh filename="package://svenzva_description/meshes/accessories/finger_standard.STL"/>
      </geometry>
      <material name="">
        <color rgba="0.898039215686275 0.917647058823529 0.929411764705882 1"/>
      </material>
    </visual>
    <collision>
      <origin rpy="0 0 0" xyz="0 0 0"/>
      <geometry>
        <mesh filename="package://svenzva_description/meshes/accessories/finger_standard.STL"/>
      </geometry>
    </collision>
  </link>
  <joint name="finger_joint_1" type="prismatic">
    <origin rpy="-3.1416 0 3.1416" xyz="0 0 -0.052002"/>
    <parent link="link_6"/>
    <child link="finger_link_1"/>
    <axis xyz="0 -1 0"/>
    <limit effort="100" lower="0" upper="0.05" velocity="10"/>
  </joint>
  <link name="finger_link_2">
    <inertial>
      <origin rpy="0 0 -1.570796" xyz="0 0 -0.003175"/>
      <mass value="0.0220307791071739"/>
      <inertia ixx="9.08331950596468E-06" ixy="-2.05394082888464E-06" ixz="-2.23772944669454E-06" iyy="1.04239718244321E-05" iyz="-2.75990314800171E-06" izz="9.60841591398502E-06"/>
    </inertial>
    <visual>
      <origin rpy="0 0 -1.570796" xyz="0 0 -0.003175"/>
      <geometry>
        <mesh filename="package://svenzva_description/meshes/accessories/finger_standard.STL"/>
      </geometry>
      <material name="">
        <color rgba="0.898039215686275 0.917647058823529 0.929411764705882 1"/>
      </material>
    </visual>
    <collision>
      <origin rpy="0 0 0" xyz="0 0 0"/>
      <geometry>
        <mesh filename="package://svenzva_description/meshes/accessories/finger_standard.STL"/>
      </geometry>
    </collision>
  </link>
  <joint name="finger_joint_2" type="prismatic">
    <origin rpy="-3.1416 0 3.1416" xyz="0 0 -0.052002"/>
    <parent link="link_6"/>
    <child link="finger_link_2"/>
    <axis xyz="0 1 0"/>
    <limit effort="100" lower="0" upper="0.05" velocity="10"/>
  </joint>
  <link name="ee_link"> </link>
  <joint name="ee_joint" type="fixed">
    <parent link="link_6"/>
    <child link="ee_link"/>
    <origin rpy="3.14159 0 0" xyz="0 0 -0.05"/>
  </joint>
  <transmission name="joint_1_trans">
    <type>transmission_interface/SimpleTransmission</type>
    <joint name="joint_1">
      <hardwareInterface>EffortJointInterface</hardwareInterface>
    </joint>
    <actuator name="motor_1">
      <mechanicalReduction>4</mechanicalReduction>
      <hardwareInterface>EffortJointInterface</hardwareInterface>
    </actuator>
  </transmission>
  <transmission name="joint_2_trans">
    <type>transmission_interface/SimpleTransmission</type>
    <joint name="joint_2">
      <hardwareInterface>EffortJointInterface</hardwareInterface>
    </joint>
    <actuator name="motor_2">
      <mechanicalReduction>6</mechanicalReduction>
      <hardwareInterface>EffortJointInterface</hardwareInterface>
    </actuator>
  </transmission>
  <transmission name="joint_3_trans">
    <type>transmission_interface/SimpleTransmission</type>
    <joint name="joint_3">
      <hardwareInterface>EffortJointInterface</hardwareInterface>
    </joint>
    <actuator name="motor_3">
      <mechanicalReduction>6</mechanicalReduction>
      <hardwareInterface>EffortJointInterface</hardwareInterface>
    </actuator>
  </transmission>
  <transmission name="joint_4_trans">
    <type>transmission_interface/SimpleTransmission</type>
    <joint name="joint_4">
      <hardwareInterface>EffortJointInterface</hardwareInterface>
    </joint>
    <actuator name="motor_4">
      <mechanicalReduction>1</mechanicalReduction>
      <hardwareInterface>EffortJointInterface</hardwareInterface>
    </actuator>
  </transmission>
  <transmission name="joint_5_trans">
    <type>transmission_interface/SimpleTransmission</type>
    <joint name="joint_5">
      <hardwareInterface>EffortJointInterface</hardwareInterface>
    </joint>
    <actuator name="motor_5">
      <mechanicalReduction>4</mechanicalReduction>
      <hardwareInterface>EffortJointInterface</hardwareInterface>
    </actuator>
  </transmission>
  <transmission name="joint_6_trans">
    <type>transmission_interface/SimpleTransmission</type>
    <joint name="joint_6">
      <hardwareInterface>EffortJointInterface</hardwareInterface>
    </joint>
    <actuator name="motor_6">
      <mechanicalReduction>1</mechanicalReduction>
      <hardwareInterface>EffortJointInterface</hardwareInterface>
    </actuator>
  </transmission>
</robot>

