<robot
  name="svenzva_arm">
  <link
    name="base_link">
    <inertial>
      <origin
        xyz="0.0282267611204656 -4.16467393532516E-06 0.0174126603947595"
        rpy="0 0 0" />
      <mass
        value="0.0723639514810396" />
      <inertia
        ixx="1.69190688470257E-05"
        ixy="7.69417521904957E-09"
        ixz="8.37951254387832E-07"
        iyy="2.98224152345193E-05"
        iyz="-4.21014817483747E-09"
        izz="2.49511572248619E-05" />
    </inertial>
    <visual>
      <origin
        xyz="0 0 0"
        rpy="0 0 0" />
      <geometry>
        <mesh
          filename="package://svenzva_description/meshes/base_link.STL" />
      </geometry>
      <material
        name="">
        <color
          rgba="0.250980392156863 0.250980392156863 0.250980392156863 1" />
      </material>
    </visual>
    <collision>
      <origin
        xyz="0 0 0"
        rpy="0 0 0" />
      <geometry>
        <mesh
          filename="package://svenzva_description/meshes/base_link.STL" />
      </geometry>
    </collision>
  </link>
  <link
    name="link_1">
    <inertial>
      <origin
        xyz="-1.92643591819981E-05 0.0612114594522474 0.00328939344318049"
        rpy="0 0 0" />
      <mass
        value="0.176002844262561" />
      <inertia
        ixx="0.000208643151707747"
        ixy="-1.86820692758146E-07"
        ixz="-1.52350104015972E-08"
        iyy="7.60585163408154E-05"
        iyz="-6.03599483310386E-06"
        izz="0.000171744611297114" />
    </inertial>
    <visual>
      <origin
        xyz="0 0 0"
        rpy="0 0 0" />
      <geometry>
        <mesh
          filename="package://svenzva_description/meshes/link_1.STL" />
      </geometry>
      <material
        name="">
        <color
          rgba="0.792156862745098 0.819607843137255 0.933333333333333 1" />
      </material>
    </visual>
    <collision>
      <origin
        xyz="0 0 0"
        rpy="0 0 0" />
      <geometry>
        <mesh
          filename="package://svenzva_description/meshes/link_1.STL" />
      </geometry>
    </collision>
  </link>
  <joint
    name="joint_1"
    type="continuous">
    <origin
      xyz="0.013 0 0.040487"
      rpy="1.5708 -1.1432E-16 -0.01434" />
    <parent
      link="base_link" />
    <child
      link="link_1" />
    <axis
      xyz="0 1 0" />
  </joint>
  <link
    name="link_2">
    <inertial>
      <origin
        xyz="7.71114209128371E-07 0.0994781017510434 0.0493225375700435"
        rpy="0 0 0" />
      <mass
        value="0.375844350415876" />
      <inertia
        ixx="0.00323830094842546"
        ixy="-1.17159810459773E-08"
        ixz="-3.5954235697731E-09"
        iyy="0.000177259939790807"
        iyz="0.000166160883723631"
        izz="0.00319740520859411" />
    </inertial>
    <visual>
      <origin
        xyz="0 0 0"
        rpy="0 0 0" />
      <geometry>
        <mesh
          filename="package://svenzva_description/meshes/link_2.STL" />
      </geometry>
      <material
        name="">
        <color
          rgba="0.898039215686275 0.917647058823529 0.929411764705882 1" />
      </material>
    </visual>
    <collision>
      <origin
        xyz="0 0 0"
        rpy="0 0 0" />
      <geometry>
        <mesh
          filename="package://svenzva_description/meshes/link_2.STL" />
      </geometry>
    </collision>
  </link>
  <joint
    name="joint_2"
    type="revolute">
    <origin
      xyz="0 0.096463 -0.02335"
      rpy="4.0919E-18 -1.3762E-14 1.6E-18"/>
      <limit effort="30" velocity="1.0" lower="-2.0" upper="2.0" />
    <parent
      link="link_1" />
    <child
      link="link_2" />
    <axis
      xyz="0 0 -1" />
  </joint>
  <link
    name="link_3">
    <inertial>
      <origin
        xyz="0.0522608589020777 -0.0250716638835445 0.00686408266309974"
        rpy="0 0 0" />
      <mass
        value="0.31163055657814" />
      <inertia
        ixx="0.000330505588977572"
        ixy="0.00034300606220869"
        ixz="-0.000112163926914392"
        iyy="0.000868674443028782"
        iyz="5.38046323987928E-05"
        izz="0.00106518851494267" />
    </inertial>
    <visual>
      <origin
        xyz="0 0 0"
        rpy="0 0 0" />
      <geometry>
        <mesh
          filename="package://svenzva_description/meshes/link_3.STL" />
      </geometry>
      <material
        name="">
        <color
          rgba="0.898039215686275 0.917647058823529 0.929411764705882 1" />
      </material>
    </visual>
    <collision>
      <origin
        xyz="0 0 0"
        rpy="0 0 0" />
      <geometry>
        <mesh
          filename="package://svenzva_description/meshes/link_3.STL" />
      </geometry>
    </collision>
  </link>
  <joint
    name="joint_3"
    type="revolute">
    <origin
      xyz="0 0.2267 0.015875"
      rpy="6.193E-16 3.5562E-16 1.9901" />
      <limit effort="30" velocity="1.0" lower="-2.0" upper="2.0" />
    <parent
      link="link_2" />
    <child
      link="link_3" />
    <axis
      xyz="0 0 -1" />
  </joint>
  <link
    name="link_4">
    <inertial>
      <origin
        xyz="-0.0327640355718256 0.0647432596593949 0.0186235506382799"
        rpy="0 0 0" />
      <mass
        value="0.227468523944598" />
      <inertia
        ixx="0.000624192810776477"
        ixy="0.000229325979885121"
        ixz="4.93064516762306E-05"
        iyy="0.000279054121470269"
        iyz="-9.74217740996892E-05"
        izz="0.000679834592641694" />
    </inertial>
    <visual>
      <origin
        xyz="0 0 0"
        rpy="0 0 0" />
      <geometry>
        <mesh
          filename="package://svenzva_description/meshes/link_4.STL" />
      </geometry>
      <material
        name="">
        <color
          rgba="0.898039215686275 0.917647058823529 0.929411764705882 1" />
      </material>
    </visual>
    <collision>
      <origin
        xyz="0 0 0"
        rpy="0 0 0" />
      <geometry>
        <mesh
          filename="package://svenzva_description/meshes/link_4.STL" />
      </geometry>
    </collision>
  </link>
  <joint
    name="joint_4"
    type="revolute">
    <origin
      xyz="0.112887803122276 -0.0849668013782555 0.0137499694500327"
      rpy="1.57079632679489 -1.08279352070304 2.72231120032224" />
    <limit effort="30" velocity="1.0" lower="-2.4" upper="2.4" />
    <parent
      link="link_3" />
    <child
      link="link_4" />
    <axis
      xyz="0 0 -1" />
  </joint>
  <link
    name="link_5">
    <inertial>
      <origin
        xyz="0.0317708193843095 0.0290627872228792 -0.0287224989128879"
        rpy="0 0 0" />
      <mass
        value="0.151584942075443" />
      <inertia
        ixx="0.000142473336923903"
        ixy="-2.5591824625033E-05"
        ixz="1.45643965384336E-05"
        iyy="0.000146187652068026"
        iyz="1.33335635590602E-05"
        izz="0.000135326937116664" />
    </inertial>
    <visual>
      <origin
        xyz="0 0 0"
        rpy="0 0 0" />
      <geometry>
        <mesh
          filename="package://svenzva_description/meshes/link_5.STL" />
      </geometry>
      <material
        name="">
        <color
          rgba="0.898039215686275 0.917647058823529 0.929411764705882 1" />
      </material>
    </visual>
    <collision>
      <origin
        xyz="0 0 0"
        rpy="0 0 0" />
      <geometry>
        <mesh
          filename="package://svenzva_description/meshes/link_5.STL" />
      </geometry>
    </collision>
  </link>
  <joint
    name="joint_5"
    type="revolute">
    <origin
      xyz="-0.0309980883229195 0.139443213449917 0.0252374943531824"
      rpy="1.57079632679489 0.745906426455644 2.05879913288675" />
    <limit effort="30" velocity="1.0" lower="-1.9" upper="1.9" />
    <parent
      link="link_4" />
    <child
      link="link_5" />
    <axis
      xyz="0 0 1" />
  </joint>
  <link
    name="link_6">
    <inertial>
      <origin
        xyz="0.000183599946350366 0.0034063471104061 -0.0422713093422175"
        rpy="0 0 0" />
      <mass
        value="0.322937867529949" />
      <inertia
        ixx="0.000416301869951862"
        ixy="-3.90872070556596E-07"
        ixz="2.31677011448052E-06"
        iyy="0.00045879271038691"
        iyz="-1.82119546859927E-05"
        izz="0.000469102213182677" />
    </inertial>
    <visual>
      <origin
        xyz="0 0 0"
        rpy="0 0 0" />
      <geometry>
        <mesh
          filename="package://svenzva_description/meshes/link_6.STL" />
      </geometry>
      <material
        name="">
        <color
          rgba="0.792156862745098 0.819607843137255 0.933333333333333 1" />
      </material>
    </visual>
    <collision>
      <origin
        xyz="0 0 0"
        rpy="0 0 0" />
      <geometry>
        <mesh
          filename="package://svenzva_description/meshes/link_6.STL" />
      </geometry>
    </collision>
  </link>
  <joint
    name="joint_6"
    type="continuous">
    <origin
      xyz="0.0527875432993938 0.0688570078944784 -0.0317500182541626"
      rpy="-1.57079632679493 1.55645636523858 2.3167027532505" />
    <parent
      link="link_5" />
    <child
      link="link_6" />
    <axis
      xyz="0 0 -1" />
  </joint>
</robot>
