<robot
  name="svenzva_arm">
  <link
    name="base_link">
    <inertial>
      <origin
        xyz="0.18306367413687 -0.0233084276298693 0.0180761484144128"
        rpy="0 0 0" />
      <mass
        value="0.0440503113116943" />
      <inertia
        ixx="1.26286826095278E-05"
        ixy="-1.40068407294705E-09"
        ixz="2.90163117696712E-11"
        iyy="7.82071230441501E-06"
        iyz="-3.61057953014731E-07"
        izz="1.04785926366992E-05" />
    </inertial>
    <visual>
      <origin
        xyz="0 0 0"
        rpy="0 0 0" />
      <geometry>
        <mesh
          filename="package://svenzva_description/meshes/base_link.STL" />
      </geometry>
      <material
        name="">
        <color
          rgba="0.792156862745098 0.819607843137255 0.933333333333333 1" />
      </material>
    </visual>
    <collision>
      <origin
        xyz="0 0 0"
        rpy="0 0 0" />
      <geometry>
        <mesh
          filename="package://svenzva_description/meshes/base_link.STL" />
      </geometry>
    </collision>
  </link>
  <link
    name="link_1">
    <inertial>
      <origin
        xyz="-0.00669571090553394 0.0388461846451639 0.00040412268555523"
        rpy="0 0 0" />
      <mass
        value="0.0925085972682552" />
      <inertia
        ixx="5.00823155961961E-05"
        ixy="9.52391117758938E-07"
        ixz="1.38353181525867E-08"
        iyy="2.49393047672637E-05"
        iyz="-1.11584585407224E-06"
        izz="4.10382695934873E-05" />
    </inertial>
    <visual>
      <origin
        xyz="0 0 0"
        rpy="0 0 0" />
      <geometry>
        <mesh
          filename="package://svenzva_description/meshes/link_1.STL" />
      </geometry>
      <material
        name="">
        <color
          rgba="0.792156862745098 0.819607843137255 0.933333333333333 1" />
      </material>
    </visual>
    <collision>
      <origin
        xyz="0 0 0"
        rpy="0 0 0" />
      <geometry>
        <mesh
          filename="package://svenzva_description/meshes/link_1.STL" />
      </geometry>
    </collision>
  </link>
  <joint
    name="joint_1"
    type="continuous">
    <origin
      xyz="0.18306 -0.012 0.0365"
      rpy="1.5708 -6.1229E-17 -1.5632" />
    <parent
      link="base_link" />
    <child
      link="link_1" />
    <axis
      xyz="0 1 0" />
  </joint>
  <link
    name="link_2">
    <inertial>
      <origin
        xyz="0.169730547677992 -0.000267822600205109 2.70292759354911E-06"
        rpy="0 0 0" />
      <mass
        value="0.111498195078862" />
      <inertia
        ixx="4.89105220783555E-05"
        ixy="2.08446050442835E-06"
        ixz="-4.88588295210895E-09"
        iyy="0.000526174960723493"
        iyz="-4.16648472352694E-09"
        izz="0.000557293305563762" />
    </inertial>
    <visual>
      <origin
        xyz="0 0 0"
        rpy="0 0 0" />
      <geometry>
        <mesh
          filename="package://svenzva_description/meshes/link_2.STL" />
      </geometry>
      <material
        name="">
        <color
          rgba="0.792156862745098 0.819607843137255 0.933333333333333 1" />
      </material>
    </visual>
    <collision>
      <origin
        xyz="0 0 0"
        rpy="0 0 0" />
      <geometry>
        <mesh
          filename="package://svenzva_description/meshes/link_2.STL" />
      </geometry>
    </collision>
  </link>
  <joint
    name="joint_2"
    type="revolute">
    <limit effort="30" velocity="3.0" lower="-2.0" upper="2.0" />
    <origin
      xyz="-0.007 0.057 0"
      rpy="1.5708 -1.3131E-15 1.5993" />
    <parent
      link="link_1" />
    <child
      link="link_2" />
    <axis
      xyz="0 -1 0" />
  </joint>
  <link
    name="link_3">
    <inertial>
      <origin
        xyz="0.104641483307686 -0.0269135497501998 -0.00380446608306266"
        rpy="0 0 0" />
      <mass
        value="0.095277105355898" />
      <inertia
        ixx="3.29577050210334E-05"
        ixy="5.18470840609156E-07"
        ixz="5.13705244462316E-06"
        iyy="0.000154303544092084"
        iyz="-2.39435291669267E-08"
        izz="0.000160305190604025" />
    </inertial>
    <visual>
      <origin
        xyz="0 0 0"
        rpy="0 0 0" />
      <geometry>
        <mesh
          filename="package://svenzva_description/meshes/link_3.STL" />
      </geometry>
      <material
        name="">
        <color
          rgba="0.792156862745098 0.819607843137255 0.933333333333333 1" />
      </material>
    </visual>
    <collision>
      <origin
        xyz="0 0 0"
        rpy="0 0 0" />
      <geometry>
        <mesh
          filename="package://svenzva_description/meshes/link_3.STL" />
      </geometry>
    </collision>
  </link>
  <joint
    name="joint_3"
    type="revolute">
    <limit effort="30" velocity="3.0" lower="-2.0" upper="2.0" />
    <origin
      xyz="0.2267 -0.026613 0"
      rpy="3.1416 0.016207 -1.4079E-15" />
    <parent
      link="link_2" />
    <child
      link="link_3" />
    <axis
      xyz="0 1 0" />
  </joint>
  <link
    name="link_4">
    <inertial>
      <origin
        xyz="0.0930650436809969 0.00334712751247027 0.00491549180258602"
        rpy="0 0 0" />
      <mass
        value="0.0630903380817815" />
      <inertia
        ixx="2.22616217444818E-05"
        ixy="2.76265285117051E-06"
        ixz="-7.50803987277438E-06"
        iyy="0.00011058046285098"
        iyz="2.63341119772391E-07"
        izz="0.000119134391315269" />
    </inertial>
    <visual>
      <origin
        xyz="0 0 0"
        rpy="0 0 0" />
      <geometry>
        <mesh
          filename="package://svenzva_description/meshes/link_4.STL" />
      </geometry>
      <material
        name="">
        <color
          rgba="0.792156862745098 0.819607843137255 0.933333333333333 1" />
      </material>
    </visual>
    <collision>
      <origin
        xyz="0 0 0"
        rpy="0 0 0" />
      <geometry>
        <mesh
          filename="package://svenzva_description/meshes/link_4.STL" />
      </geometry>
    </collision>
  </link>
  <joint
    name="joint_4"
    type="revolute">
    <limit effort="30" velocity="3.0" lower="-2.0" upper="2.0" />
    <origin
      xyz="0.1377 -0.027013 0"
      rpy="-1.5708 -9.0206E-16 -0.00096517" />
    <parent
      link="link_3" />
    <child
      link="link_4" />
    <axis
      xyz="0 1 0" />
  </joint>
  <link
    name="link_5">
    <inertial>
      <origin
        xyz="-0.0510929189416032 -0.00750067832893903 0.00565598618945352"
        rpy="0 0 0" />
      <mass
        value="0.0564481780820506" />
      <inertia
        ixx="1.76538077615809E-05"
        ixy="-1.46152633641033E-07"
        ixz="2.64184773175431E-06"
        iyy="3.53012634557871E-05"
        iyz="2.44903631075645E-08"
        izz="3.47267638978701E-05" />
    </inertial>
    <visual>
      <origin
        xyz="0 0 0"
        rpy="0 0 0" />
      <geometry>
        <mesh
          filename="package://svenzva_description/meshes/link_5.STL" />
      </geometry>
      <material
        name="">
        <color
          rgba="0.792156862745098 0.819607843137255 0.933333333333333 1" />
      </material>
    </visual>
    <collision>
      <origin
        xyz="0 0 0"
        rpy="0 0 0" />
      <geometry>
        <mesh
          filename="package://svenzva_description/meshes/link_5.STL" />
      </geometry>
    </collision>
  </link>
  <joint
    name="joint_5"
    type="revolute">
    <limit effort="30" velocity="3.0" lower="-1.55" upper="1.65" />
    <origin
      xyz="0.1282 0.0025 0"
      rpy="-1.5708 4.6139E-15 3.1385" />
    <parent
      link="link_4" />
    <child
      link="link_5" />
    <axis
      xyz="0 -1 0" />
  </joint>
  <link
    name="link_6">
    <inertial>
      <origin
        xyz="0.000228248674263673 1.43601829790396E-05 0.0369844197734914"
        rpy="0 0 0" />
      <mass
        value="0.110167061775322" />
      <inertia
        ixx="0.000135642932219405"
        ixy="-6.31183914212531E-07"
        ixz="-9.75038825730203E-06"
        iyy="9.85299581174772E-05"
        iyz="1.80458524249379E-07"
        izz="6.68262642530766E-05" />
    </inertial>
    <visual>
      <origin
        xyz="0 0 0"
        rpy="0 0 0" />
      <geometry>
        <mesh
          filename="package://svenzva_description/meshes/link_6.STL" />
      </geometry>
      <material
        name="">
        <color
          rgba="1 0.815686274509804 0.403921568627451 1" />
      </material>
    </visual>
    <collision>
      <origin
        xyz="0 0 0"
        rpy="0 0 0" />
      <geometry>
        <mesh
          filename="package://svenzva_description/meshes/link_6.STL" />
      </geometry>
    </collision>
  </link>
  <joint
    name="joint_6"
    type="continuous">
    <origin
      xyz="-0.083813 -0.007575 -0.004"
      rpy="1.5708 -1.5649 -1.5708" />
    <parent
      link="link_5" />
    <child
      link="link_6" />
    <axis
      xyz="0 0 1" />
  </joint>
</robot>
