<robot
  name="svenzva_description">
  <link
    name="base_link">
    <inertial>
      <origin
        xyz="0.028227 -4.1647E-06 0.017413"
        rpy="0 0 0" />
      <mass
        value="0.072364" />
      <inertia
        ixx="1.6919E-05"
        ixy="7.6942E-09"
        ixz="8.3795E-07"
        iyy="2.9822E-05"
        iyz="-4.2101E-09"
        izz="2.4951E-05" />
    </inertial>
    <visual>
      <origin
        xyz="0 0 0"
        rpy="0 0 0" />
      <geometry>
        <mesh
          filename="package://svenzva_description/meshes/base_link.STL" />
      </geometry>
      <material
        name="">
        <color
          rgba="0.25098 0.25098 0.25098 1" />
      </material>
    </visual>
    <collision>
      <origin
        xyz="0 0 0"
        rpy="0 0 0" />
      <geometry>
        <mesh
          filename="package://svenzva_description/meshes/base_link.STL" />
      </geometry>
    </collision>
  </link>
  <link
    name="link_1">
    <inertial>
      <origin
        xyz="-1.92637189363339E-05 0.0612114594522473 0.00328939346168595"
        rpy="0 0 0" />
      <mass
        value="0.176002844262561" />
      <inertia
        ixx="0.000208643151876583"
        ixy="-1.86819667582171E-07"
        ixz="-1.52379484078016E-08"
        iyy="7.60585165139914E-05"
        iyz="-6.03599480455551E-06"
        izz="0.000171744611301454" />
    </inertial>
    <visual>
      <origin
        xyz="0 0 0"
        rpy="0 0 0" />
      <geometry>
        <mesh
          filename="package://svenzva_description/meshes/link_1.STL" />
      </geometry>
      <material
        name="">
        <color
          rgba="0.792156862745098 0.819607843137255 0.933333333333333 1" />
      </material>
    </visual>
    <collision>
      <origin
        xyz="0 0 0"
        rpy="0 0 0" />
      <geometry>
        <mesh
          filename="package://svenzva_description/meshes/link_1.STL" />
      </geometry>
    </collision>
  </link>
  <joint
    name="joint_1"
    type="revolute">
    <limit effort="30" velocity="1.0" lower="0.0" upper="6.0" />
    <origin
      xyz="0.013 0 0.040487"
      rpy="1.5708 -1.1432E-16 -0.01434" />
    <parent
      link="base_link" />
    <child
      link="link_1" />
    <axis
      xyz="0 1 0" />
  </joint>
  <link
    name="link_2">
    <inertial>
      <origin
        xyz="0.000242092958416362 0.0994778071717372 0.0493225375612701"
        rpy="0 0 0" />
      <mass
        value="0.375844350417551" />
      <inertia
        ixx="0.00323828287771197"
        ixy="-7.43740952739379E-06"
        ixz="3.99490816185825E-07"
        iyy="0.000177278010521242"
        iyz="0.000166160403527079"
        izz="0.00319740520861273" />
    </inertial>
    <visual>
      <origin
        xyz="0 0 0"
        rpy="0 0 0" />
      <geometry>
        <mesh
          filename="package://svenzva_description/meshes/link_2.STL" />
      </geometry>
      <material
        name="">
        <color
          rgba="0.898039215686275 0.917647058823529 0.929411764705882 1" />
      </material>
    </visual>
    <collision>
      <origin
        xyz="0 0 0"
        rpy="0 0 0" />
      <geometry>
        <mesh
          filename="package://svenzva_description/meshes/link_2.STL" />
      </geometry>
    </collision>
  </link>
  <joint
    name="joint_2"
    type="revolute">
    <limit effort="30" velocity="1.0" lower="-2.0" upper="2.0" />
    <origin
      xyz="0 0.0964625315349195 -0.0233499999819998"
      rpy="4.09187004857075E-18 -1.3761561334924E-14 1.60002689098321E-18" />
    <parent
      link="link_1" />
    <child
      link="link_2" />
    <axis
      xyz="0 0 -1" />
  </joint>
  <link
    name="link_3">
    <inertial>
      <origin
        xyz="0.00203426609326087 0.0579453135114721 0.00686408266309166"
        rpy="0 0 0" />
      <mass
        value="0.31163055657781" />
      <inertia
        ixx="0.00103470545222349"
        ixy="-2.70938275918836E-05"
        ixz="-3.18115479492875E-06"
        iyy="0.000164474500269926"
        iyz="-0.000124360617659833"
        izz="0.00106518843542982" />
    </inertial>
    <visual>
      <origin
        xyz="0 0 0"
        rpy="0 0 0" />
      <geometry>
        <mesh
          filename="package://svenzva_description/meshes/link_3.STL" />
      </geometry>
      <material
        name="">
        <color
          rgba="0.898039215686275 0.917647058823529 0.929411764705882 1" />
      </material>
    </visual>
    <collision>
      <origin
        xyz="0 0 0"
        rpy="0 0 0" />
      <geometry>
        <mesh
          filename="package://svenzva_description/meshes/link_3.STL" />
      </geometry>
    </collision>
  </link>
  <joint
    name="joint_3"
    type="revolute">
    <limit effort="30" velocity="1.0" lower="-2.0" upper="2.0" />
    <origin
      xyz="0 0.22669999999 0.0158749999819999"
      rpy="6.69447407664753E-16 1.6306400674182E-16 -0.00242557244235328" />
    <parent
      link="link_2" />
    <child
      link="link_3" />
    <axis
      xyz="0 0 1" />
  </joint>
  <link
    name="link_4">
    <inertial>
      <origin
        xyz="-0.00141616334293113 0.072547694177152 0.0041139013703472"
        rpy="0 0 0" />
      <mass
        value="0.227468523944588" />
      <inertia
        ixx="0.000738263046037403"
        ixy="1.44338129581601E-05"
        ixz="-2.1264897532628E-06"
        iyy="0.000164984008803471"
        iyz="0.000109168078846722"
        izz="0.000679834470047577" />
    </inertial>
    <visual>
      <origin
        xyz="0 0 0"
        rpy="0 0 0" />
      <geometry>
        <mesh
          filename="package://svenzva_description/meshes/link_4.STL" />
      </geometry>
      <material
        name="">
        <color
          rgba="0.898039215686275 0.917647058823529 0.929411764705882 1" />
      </material>
    </visual>
    <collision>
      <origin
        xyz="0 0 0"
        rpy="0 0 0" />
      <geometry>
        <mesh
          filename="package://svenzva_description/meshes/link_4.STL" />
      </geometry>
    </collision>
  </link>
  <joint
    name="joint_4"
    type="revolute">
    <limit effort="30" velocity="1.0" lower="-2.4" upper="2.4" />
    <origin
      xyz="0.00912959083561864 0.137721791833396 0.0137499861543416"
      rpy="-2.36709870890947 1.57079630572147 -2.36079769092609" />
    <parent
      link="link_3" />
    <child
      link="link_4" />
    <axis
      xyz="0 0 -1.0" />
  </joint>
  <link
    name="link_5">
    <inertial>
      <origin
        xyz="-0.000214561294726828 0.0430579287664379 -0.0157275010872988"
        rpy="0 0 0" />
      <mass
        value="0.151584942075443" />
      <inertia
        ixx="0.000169989064033342"
        ixy="-1.68318690269819E-07"
        ixz="9.0631646634003E-08"
        iyy="0.000118671924958588"
        iyz="-1.97458185349935E-05"
        izz="0.000135326937116664" />
    </inertial>
    <visual>
      <origin
        xyz="0 0 0"
        rpy="0 0 0" />
      <geometry>
        <mesh
          filename="package://svenzva_description/meshes/link_5.STL" />
      </geometry>
      <material
        name="">
        <color
          rgba="0.898039215686275 0.917647058823529 0.929411764705882 1" />
      </material>
    </visual>
    <collision>
      <origin
        xyz="0 0 0"
        rpy="0 0 0" />
      <geometry>
        <mesh
          filename="package://svenzva_description/meshes/link_5.STL" />
      </geometry>
    </collision>
  </link>
  <joint
    name="joint_5"
    type="revolute">
    <limit effort="30" velocity="1.0" lower="-1.9" upper="1.9" />
    <origin
      xyz="0.00645000003795365 0.1377 -0.00249999436214027"
      rpy="0 1.5707963267949 0" />
    <parent
      link="link_4" />
    <child
      link="link_5" />
    <axis
      xyz="0 0 1" />
  </joint>
  <link
    name="link_6">
    <inertial>
      <origin
        xyz="0.000175681110397272 -0.00395853081853387 0.0422705829486781"
        rpy="0 0 0" />
      <mass
        value="0.322937867529949" />
      <inertia
        ixx="0.000416301869951863"
        ixy="3.90872070556568E-07"
        ixz="-2.31677011448066E-06"
        iyy="0.000458792710386911"
        iyz="-1.82119546859927E-05"
        izz="0.000469102213182677" />
    </inertial>
    <visual>
      <origin
        xyz="0 0 0"
        rpy="0 0 0" />
      <geometry>
        <mesh
          filename="package://svenzva_description/meshes/link_6.STL" />
      </geometry>
      <material
        name="">
        <color
          rgba="0.792156862745098 0.819607843137255 0.933333333333333 1" />
      </material>
    </visual>
    <collision>
      <origin
        xyz="0 0 0"
        rpy="0 0 0" />
      <geometry>
        <mesh
          filename="package://svenzva_description/meshes/link_6.STL" />
      </geometry>
    </collision>
  </link>
  <joint
    name="joint_6"
    type="continuous">
    <origin
      xyz="0.0153032852422354 0.0855005794492288 -0.0126999817460203"
      rpy="-1.5707963267949 -1.55645636523858 -1.09070333872558E-05" />
    <parent
      link="link_5" />
    <child
      link="link_6" />
    <axis
      xyz="0 0 1" />
  </joint>

  <link name="ee_link"> </link>
  
  <joint name="ee_joint" type="fixed">
    <parent link="link_6"/>
    <child link="ee_link"/>
    <origin xyz="0.015 0 0.15"/>
  </joint>

</robot>
