<robot name="revel">
   <gazebo>
     <plugin name="gazebo_ros_control" filename="libgazebo_ros_control.so">
       <robotNamespace>/revel/</robotNamespace>
     </plugin>
   </gazebo>

  <link name="world"/>
  <link name="base_link">
    <inertial>
      <origin
        xyz="-0.00133562616624824 -0.00299591002016462 0.0153449295508581"
        rpy="0 0 0" />
      <mass
        value="0.722020764728074" />
      <inertia
        ixx="0.00192032665135544"
        ixy="-1.38171436818506E-05"
        ixz="7.88915046947883E-06"
        iyy="0.00186797485168719"
        iyz="3.14817845967135E-05"
        izz="0.00316707992917207" />
    </inertial>
    <visual>
      <origin
        xyz="0 0 0"
        rpy="0 0 0" />
      <geometry>
        <mesh
          filename="package://svenzva_description/meshes/base_link.STL" />
      </geometry>
      <material
        name="">
        <color
          rgba="0.898039215686275 0.917647058823529 0.929411764705882 1" />
      </material>
    </visual>
    <collision>
      <origin
        xyz="0 0 0"
        rpy="0 0 0" />
      <geometry>
        <mesh
          filename="package://svenzva_description/meshes/base_link.STL" />
      </geometry>
    </collision>
  </link>

  <joint name="world_joint" type="fixed">
    <parent link="world"/>
    <child link="base_link"/>
  </joint>

  <link
    name="link_1">
    <inertial>
      <origin
        xyz="-0.00528149564542819 2.92409530103649E-05 0.0481308455186285"
        rpy="0 0 0" />
      <mass
        value="0.095038974095265" />
      <inertia
        ixx="0.00048302"
        ixy="0.00058791"
        ixz="2.1e-7"
        iyy="3.938e-5"
        iyz="1.7e-7"
        izz="2.65e-5" />
    </inertial>
    <visual>
      <origin
        xyz="0 0 0"
        rpy="0 0 0" />
      <geometry>
        <mesh
          filename="package://svenzva_description/meshes/link_1.STL" />
      </geometry>
      <material
        name="">
        <color
          rgba="0.898039215686275 0.917647058823529 0.929411764705882 1" />
      </material>
    </visual>
    <collision>
      <origin
        xyz="0 0 0"
        rpy="0 0 0" />
      <geometry>
        <mesh
          filename="package://svenzva_description/meshes/link_1.STL" />
      </geometry>
    </collision>
  </link>
  <joint
    name="joint_1"
    type="revolute">
    <origin
      xyz="0 0 0.0762"
      rpy="0 0 0" />
    <parent
      link="base_link" />
    <child
      link="link_1" />
    <axis
      xyz="0 0 -1" />
    <limit
      lower="-3.14"
      upper="3.14"
      effort="100"
      velocity="10" />
  </joint>
  <link
    name="link_2">
    <inertial>
      <origin
        xyz="8.17940782230075E-07 0.125408839850757 0.0120693662786398"
        rpy="0 0 0" />
      <mass
        value="0.350557648873674" />
      <inertia
        ixx="0.00290049583666862"
        ixy="-4.66260243339681E-09"
        ixz="-1.74520760929758E-09"
        iyy="0.000201563465404586"
        iyz="0.000261870918148287"
        izz="0.00282768721300917" />
    </inertial>
    <visual>
      <origin
        xyz="0 0 0"
        rpy="0 0 0" />
      <geometry>
        <mesh
          filename="package://svenzva_description/meshes/link_2.STL" />
      </geometry>
      <material
        name="">
        <color
          rgba="0.898039215686275 0.917647058823529 0.929411764705882 1" />
      </material>
    </visual>
    <collision>
      <origin
        xyz="0 0 0"
        rpy="0 0 0" />
      <geometry>
        <mesh
          filename="package://svenzva_description/meshes/link_2.STL" />
      </geometry>
    </collision>
  </link>
  <joint
    name="joint_2"
    type="revolute">
    <origin
      xyz="-0.007325 0 0.10542"
      rpy="1.5708 0 -1.5708" />
    <parent
      link="link_1" />
    <child
      link="link_2" />
    <axis
      xyz="0 0 -1" />
    <limit
      lower="-2"
      upper="2"
      effort="100"
      velocity="10" />
  </joint>
  <link
    name="link_3">
    <inertial>
      <origin
        xyz="-0.00224918997054324 0.0725742731372729 0.0140957004144005"
        rpy="0 0 0" />
      <mass
        value="0.285860881806706" />
      <inertia
        ixx=".037638726"
        ixy="-0.000981953"
        ixz="-0.000055716"
        iyy="0.002015035"
        iyz="0.001841555"
        izz="0.037151960" />
    </inertial>
    <visual>
      <origin
        xyz="0 0 0"
        rpy="0 0 0" />
      <geometry>
        <mesh
          filename="package://svenzva_description/meshes/link_3.STL" />
      </geometry>
      <material
        name="">
        <color
          rgba="0.898039215686275 0.917647058823529 0.929411764705882 1" />
      </material>
    </visual>
    <collision>
      <origin
        xyz="0 0 0"
        rpy="0 0 0" />
      <geometry>
        <mesh
          filename="package://svenzva_description/meshes/link_3.STL" />
      </geometry>
    </collision>
  </link>
  <joint
    name="joint_3"
    type="revolute">
    <origin
      xyz="0 0.2277 0.00635"
      rpy="3.1416 0 3.1416" />
    <parent
      link="link_2" />
    <child
      link="link_3" />
    <axis
      xyz="0 0 -1" />
    <limit
      lower="-2"
      upper="2"
      effort="100"
      velocity="10" />
  </joint>
  <link
    name="link_4">
    <inertial>
      <origin
        xyz="4.94200978125581E-05 0.00446272782448867 0.0502025183837943"
        rpy="0 0 0" />
      <mass
        value="0.236769" />
      <inertia
        ixx="0.0070477"
        ixy="-0.000006265"
        ixz="0.000000363"
        iyy="0.006356422"
        iyz="0.000438258"
        izz="0.001135842" />
    </inertial>
    <visual>
      <origin
        xyz="0 0 0"
        rpy="0 0 0" />
      <geometry>
        <mesh
          filename="package://svenzva_description/meshes/link_4.STL" />
      </geometry>
      <material
        name="">
        <color
          rgba="0.898039215686275 0.917647058823529 0.929411764705882 1" />
      </material>
    </visual>
    <collision>
      <origin
        xyz="0 0 0"
        rpy="0 0 0" />
      <geometry>
        <mesh
          filename="package://svenzva_description/meshes/link_4.STL" />
      </geometry>
    </collision>
  </link>
  <joint
    name="joint_4"
    type="revolute">
    <origin
      xyz="-0.022225 0.17977 0.0074"
      rpy="1.5708 0 -3.1416" />
    <parent
      link="link_3" />
    <child
      link="link_4" />
    <axis
      xyz="0 0 1" />
    <limit
      lower="-3"
      upper="3"
      effort="10"
      velocity="1" />
  </joint>
  <link
    name="link_5">
    <inertial>
      <origin
        xyz="0.000241023608886559 0.0392574508036669 0.00184531476783182"
        rpy="0 0 0" />
      <mass
        value="0.133021865517638" />
      <inertia
        ixx="0.000108599166071625"
        ixy="3.76551051091788E-07"
        ixz="5.63803866067119E-09"
        iyy="9.94865517767143E-05"
        iyz="2.18016588858829E-06"
        izz="9.08075415393567E-05" />
    </inertial>
    <visual>
      <origin
        xyz="0 0 0"
        rpy="0 0 0" />
      <geometry>
        <mesh
          filename="package://svenzva_description/meshes/link_5.STL" />
      </geometry>
      <material
        name="">
        <color
          rgba="0.898039215686275 0.917647058823529 0.929411764705882 1" />
      </material>
    </visual>
    <collision>
      <origin
        xyz="0 0 0"
        rpy="0 0 0" />
      <geometry>
        <mesh
          filename="package://svenzva_description/meshes/link_5.STL" />
      </geometry>
    </collision>
  </link>
  <joint
    name="joint_5"
    type="revolute">
    <origin
      xyz="0 0.00165 0.07925"
      rpy="1.5708 0 -3.1416" />
    <parent
      link="link_4" />
    <child
      link="link_5" />
    <axis
      xyz="0 0 -1" />
    <limit
      lower="-1.7"
      upper="1.7"
      effort="100"
      velocity="10" />
  </joint>
  <link
    name="link_6">
    <inertial>
      <origin
        xyz="-0.00459904693334756 2.57945888126887E-05 -0.0327482586471116"
        rpy="0 0 0" />
      <mass
        value="0.243320868551208" />
      <inertia
        ixx="0.00016020334766947"
        ixy="-3.96748456837556E-06"
        ixz="1.08510273443082E-05"
        iyy="0.000326394043482595"
        iyz="1.11931196964281E-08"
        izz="0.000294334543327469" />
    </inertial>
    <visual>
      <origin
        xyz="0 0 0"
        rpy="0 0 0" />
      <geometry>
        <mesh
          filename="package://svenzva_description/meshes/link_6.STL" />
      </geometry>
      <material
        name="">
        <color
          rgba="0.250980392156863 0.250980392156863 0.250980392156863 1" />
      </material>
    </visual>
    <collision>
      <origin
        xyz="0 0 0"
        rpy="0 0 0" />
      <geometry>
        <mesh
          filename="package://svenzva_description/meshes/link_6.STL" />
      </geometry>
    </collision>
  </link>
  <joint
    name="joint_6"
    type="revolute">
    <origin
      xyz="-0.01475 0.08 0.001425"
      rpy="1.5708 0 0" />
    <parent
      link="link_5" />
    <child
      link="link_6" />
    <axis
      xyz="0 0 -1" />
    <limit
      lower="-1.6"
      upper="1.6"
      effort="100"
      velocity="10" />
  </joint>
  <link
    name="finger_link_1">
    <inertial>
      <origin
        xyz="-0.00483282204262809 -0.00411403012500923 0.0206210772714723"
        rpy="0 0 1.5708" />
      <mass
        value="0.0220307791071739" />
      <inertia
        ixx="9.08331950596468E-06"
        ixy="-2.05394082888464E-06"
        ixz="-2.23772944669454E-06"
        iyy="1.04239718244321E-05"
        iyz="-2.75990314800171E-06"
        izz="9.60841591398502E-06" />
    </inertial>
    <visual>
      <origin
        xyz="0 0 0"
        rpy="0 0 1.5708" />
      <geometry>
        <mesh
          filename="package://svenzva_description/meshes/finger_link_1.STL" />
      </geometry>
      <material
        name="">
        <color
          rgba="0.898039215686275 0.917647058823529 0.929411764705882 1" />
      </material>
    </visual>
    <collision>
      <origin
        xyz="0 0 0"
        rpy="0 0 0" />
      <geometry>
        <mesh
          filename="package://svenzva_description/meshes/finger_link_1.STL" />
      </geometry>
    </collision>
  </link>
  <joint
    name="finger_joint_1"
    type="prismatic">
    <origin
      xyz="0 0 -0.052509"
      rpy="-3.1416 -1.8964E-18 3.1416" />
    <parent
      link="link_6" />
    <child
      link="finger_link_1" />
    <axis
      xyz="-1 0 0" />
    <limit
      lower="0"
      upper="0.05"
      effort="100"
      velocity="10" />
  </joint>
  <link
    name="finger_joint_2">
    <inertial>
      <origin
        xyz="0.00483282233149502 0.00411402197005728 0.020621076918268"
        rpy="0 0 1.5708" />
      <mass
        value="0.0220307791071739" />
      <inertia
        ixx="9.08331950596466E-06"
        ixy="-2.05394082888463E-06"
        ixz="2.23772944669453E-06"
        iyy="1.04239718244321E-05"
        iyz="2.75990314800169E-06"
        izz="9.60841591398501E-06" />
    </inertial>
    <visual>
      <origin
        xyz="0 0 0"
        rpy="0 0 1.5708" />
      <geometry>
        <mesh
          filename="package://svenzva_description/meshes/finger_joint_2.STL" />
      </geometry>
      <material
        name="">
        <color
          rgba="0.898039215686275 0.917647058823529 0.929411764705882 1" />
      </material>
    </visual>
    <collision>
      <origin
        xyz="0 0 0"
        rpy="0 0 0" />
      <geometry>
        <mesh
          filename="package://svenzva_description/meshes/finger_joint_2.STL" />
      </geometry>
    </collision>
  </link>
  <joint
    name="finger_joint_2"
    type="prismatic">
    <origin
      xyz="0 0 -0.052509"
      rpy="-3.1416 -1.8964E-18 3.1416" />
    <parent
      link="link_6" />
    <child
      link="finger_joint_2" />
    <axis
      xyz="-1 0 0" />
    <limit
      lower="-0.05"
      upper="0"
      effort="100"
      velocity="10" />
  </joint>


  <transmission name="joint_1_trans">
    <type>transmission_interface/SimpleTransmission</type>
    <joint name="joint_1">
      <hardwareInterface>EffortJointInterface</hardwareInterface>
    </joint>
    <actuator name="motor_1">
      <mechanicalReduction>4</mechanicalReduction>
      <hardwareInterface>EffortJointInterface</hardwareInterface>
    </actuator>
  </transmission>

  <transmission name="joint_2_trans">
    <type>transmission_interface/SimpleTransmission</type>
    <joint name="joint_2">
      <hardwareInterface>EffortJointInterface</hardwareInterface>
    </joint>
  <actuator name="motor_2">
    <mechanicalReduction>6</mechanicalReduction>
    <hardwareInterface>EffortJointInterface</hardwareInterface>
  </actuator>
  </transmission>

  <transmission name="joint_3_trans">
    <type>transmission_interface/SimpleTransmission</type>
    <joint name="joint_3">
      <hardwareInterface>EffortJointInterface</hardwareInterface>
    </joint>
  <actuator name="motor_3">
    <mechanicalReduction>6</mechanicalReduction>
    <hardwareInterface>EffortJointInterface</hardwareInterface>
  </actuator>
  </transmission>

  <transmission name="joint_4_trans">
    <type>transmission_interface/SimpleTransmission</type>
    <joint name="joint_4">
      <hardwareInterface>EffortJointInterface</hardwareInterface>
    </joint>
  <actuator name="motor_4">
    <mechanicalReduction>1</mechanicalReduction>
    <hardwareInterface>EffortJointInterface</hardwareInterface>
  </actuator>
  </transmission>

  <transmission name="joint_5_trans">
    <type>transmission_interface/SimpleTransmission</type>
    <joint name="joint_5">
      <hardwareInterface>EffortJointInterface</hardwareInterface>
    </joint>
  <actuator name="motor_5">
    <mechanicalReduction>4</mechanicalReduction>
    <hardwareInterface>EffortJointInterface</hardwareInterface>
  </actuator>
  </transmission>

  <transmission name="joint_6_trans">
    <type>transmission_interface/SimpleTransmission</type>
    <joint name="joint_6">
      <hardwareInterface>EffortJointInterface</hardwareInterface>
    </joint>
  <actuator name="motor_6">
    <mechanicalReduction>1</mechanicalReduction>
    <hardwareInterface>EffortJointInterface</hardwareInterface>
  </actuator>
  </transmission>


</robot>
