<robot name="revel">
   <gazebo>
     <plugin name="gazebo_ros_control" filename="libgazebo_ros_control.so">
       <robotNamespace>/revel/</robotNamespace>
     </plugin>
   </gazebo>

    <link name="world"/>

    <link
    name="base_link">
    <inertial>
      <origin
        xyz="-0.00126665261387236 -0.00244642678986311 0.0184450079386729"
        rpy="0 0 0" />
      <mass
        value="0.761337238502044" />
      <inertia
        ixx="0.0020453842804903"
        ixy="-1.43470370724492E-05"
        ixz="4.8995895527518E-06"
        iyy="0.00200071769187068"
        iyz="1.33787005826615E-05"
        izz="0.00316605842402433" />
    </inertial>
    <visual>
      <origin
        xyz="0 0 0"
        rpy="0 0 0" />
      <geometry>
        <mesh
          filename="package://svenzva_description/meshes/base_link.STL" />
      </geometry>
      <material
        name="">
        <color
          rgba="0.898039215686275 0.917647058823529 0.929411764705882 1" />
      </material>
    </visual>
    <collision>
      <origin
        xyz="0 0 0"
        rpy="0 0 0" />
      <geometry>
        <mesh
          filename="package://svenzva_description/meshes/base_link.STL" />
      </geometry>
      <surface>
        <friction>
          <ode><mu>10000.0</mu><mu2>10000.0</mu2></ode>
        </friction>
      </surface>
    </collision>
  </link>
  
  <joint name="world_joint" type="fixed">
    <parent link="world"/>
    <child link="base_link"/>
  </joint>
  
  <link
    name="link_1">
    <inertial>
      <origin
        xyz="-0.0052814956454282 2.92409530103371E-05 0.0481308455186286"
        rpy="0 0 0" />
      <mass
        value="0.295038974095265" />
      <inertia
        ixx="0.000602988556413193"
        ixy="1.76219719459096E-09"
        ixz="5.7428869750627E-05"
        iyy="0.000654953956407551"
        iyz="2.88195997194139E-07"
        izz="0.000153905341508729" />
    </inertial>
    <visual>
      <origin
        xyz="0 0 0"
        rpy="0 0 0" />
      <geometry>
        <mesh
          filename="package://svenzva_description/meshes/link_1.STL" />
      </geometry>
      <material
        name="">
        <color
          rgba="0.898039215686275 0.917647058823529 0.929411764705882 1" />
      </material>
    </visual>
    <collision>
      <origin
        xyz="0 0 0"
        rpy="0 0 0" />
      <geometry>
        <mesh
          filename="package://svenzva_description/meshes/link_1.STL" />
      </geometry>
    </collision>
  </link>
  <joint
    name="joint_1"
    type="revolute">
    <origin
      xyz="0 0 0.0762"
      rpy="0 0 -4.404E-17" />
    <parent
      link="base_link" />
    <child
      link="link_1" />
    <axis
      xyz="0 0 -1" />
    <limit
      lower="-3.14"
      upper="3.14"
      effort="0"
      velocity="0" />
  </joint>
  <link
    name="link_2">
    <inertial>
      <origin
        xyz="8.32610049628091E-07 0.11949058572894 0.0121926762498804"
        rpy="0 0 0" />
      <mass
        value="0.344381379534998" />
      <inertia
        ixx="0.00284991805712312"
        ixy="-6.35957537886936E-09"
        ixz="-1.70985027691838E-09"
        iyy="0.00019516648672943"
        iyz="0.00023450953851523"
        izz="0.00278328071725567" />
    </inertial>
    <visual>
      <origin
        xyz="0 0 0"
        rpy="0 0 0" />
      <geometry>
        <mesh
          filename="package://svenzva_description/meshes/link_2.STL" />
      </geometry>
      <material
        name="">
        <color
          rgba="0.898039215686275 0.917647058823529 0.929411764705882 1" />
      </material>
    </visual>
    <collision>
      <origin
        xyz="0 0 0"
        rpy="0 0 0" />
      <geometry>
        <mesh
          filename="package://svenzva_description/meshes/link_2.STL" />
      </geometry>
    </collision>
  </link>
  <joint
    name="joint_2"
    type="revolute">
    <origin
      xyz="-0.007325 0 0.10542"
      rpy="1.5708 0 -1.5708" />
    <parent
      link="link_1" />
    <child
      link="link_2" />
    <axis
      xyz="0 0 -1" />
    <limit
      lower="-2"
      upper="2"
      effort="0"
      velocity="0" />
  </joint>
  <link
    name="link_3">
    <inertial>
      <origin
        xyz="-0.00197019590868237 0.0426227538119848 0.0168830000311054"
        rpy="0 0 0" />
      <mass
        value="0.196650631153951" />
      <inertia
        ixx="0.000427709874683083"
        ixy="1.96165723007484E-05"
        ixz="-3.81523166042413E-06"
        iyy="0.000103284735637014"
        iyz="5.91659027527963E-05"
        izz="0.00043375428535126" />
    </inertial>
    <visual>
      <origin
        xyz="0 0 0"
        rpy="0 0 0" />
      <geometry>
        <mesh
          filename="package://svenzva_description/meshes/link_3.STL" />
      </geometry>
      <material
        name="">
        <color
          rgba="0.898039215686275 0.917647058823529 0.929411764705882 1" />
      </material>
    </visual>
    <collision>
      <origin
        xyz="0 0 0"
        rpy="0 0 0" />
      <geometry>
        <mesh
          filename="package://svenzva_description/meshes/link_3.STL" />
      </geometry>
    </collision>
  </link>
  <joint
    name="joint_3"
    type="revolute">
    <origin
      xyz="0 0.2277 0.00635"
      rpy="3.1416 -2.0986E-16 3.1416" />
    <parent
      link="link_2" />
    <child
      link="link_3" />
    <axis
      xyz="0 0 -1" />
    <limit
      lower="-2"
      upper="2"
      effort="0"
      velocity="0" />
  </joint>
  <link
    name="link_4">
    <inertial>
      <origin
        xyz="-0.00513228807023979 -1.92178228225759E-05 0.0512280578881177"
        rpy="0 0 0" />
      <mass
        value="0.171727164051589" />
      <inertia
        ixx="0.000148940186221268"
        ixy="-2.95237943712108E-09"
        ixz="1.55318077169264E-05"
        iyy="0.000197291015634773"
        iyz="1.20466520102336E-08"
        izz="8.7282898263609E-05" />
    </inertial>
    <visual>
      <origin
        xyz="0 0 0"
        rpy="0 0 0" />
      <geometry>
        <mesh
          filename="package://svenzva_description/meshes/link_4.STL" />
      </geometry>
      <material
        name="">
        <color
          rgba="0.792156862745098 0.819607843137255 0.933333333333333 1" />
      </material>
    </visual>
    <collision>
      <origin
        xyz="0 0 0"
        rpy="0 0 0" />
      <geometry>
        <mesh
          filename="package://svenzva_description/meshes/link_4.STL" />
      </geometry>
    </collision>
  </link>
  <joint
    name="joint_4"
    type="revolute">
    <origin
      xyz="-0.020448 0.11835 0.0083512"
      rpy="-1.5672 1.5708 0" />
    <parent
      link="link_3" />
    <child
      link="link_4" />
    <axis
      xyz="0 0 1" />
    <limit
      lower="-5.0"
      upper="3.867165"
      effort="0"
      velocity="0" />
  </joint>
  <link
    name="link_5">
    <inertial>
      <origin
        xyz="0.00036477266016724 0.0375145178001142 0.000241811970300506"
        rpy="0 0 0" />
      <mass
        value="0.13919813472784" />
      <inertia
        ixx="0.000125530449074806"
        ixy="2.55442721360288E-07"
        ixz="-6.79678647316977E-08"
        iyy="0.000107317847378674"
        iyz="-6.19328117992915E-06"
        izz="0.000100129779938874" />
    </inertial>
    <visual>
      <origin
        xyz="0 0 0"
        rpy="0 0 0" />
      <geometry>
        <mesh
          filename="package://svenzva_description/meshes/link_5.STL" />
      </geometry>
      <material
        name="">
        <color
          rgba="0.898039215686275 0.917647058823529 0.929411764705882 1" />
      </material>
    </visual>
    <collision>
      <origin
        xyz="0 0 0"
        rpy="0 0 0" />
      <geometry>
        <mesh
          filename="package://svenzva_description/meshes/link_5.STL" />
      </geometry>
    </collision>
  </link>
  <joint
    name="joint_5"
    type="revolute">
    <origin
      xyz="-0.0010724 -2.0879E-05 0.08245"
      rpy="1.5708 -0.0035837 -1.5708" />
    <parent
      link="link_4" />
    <child
      link="link_5" />
    <axis
      xyz="0 0 -1" />
    <limit
      lower="-1.7"
      upper="1.7"
      effort="0"
      velocity="0" />
  </joint>
  <link
    name="link_6">
    <inertial>
      <origin
        xyz="2.57945868827325E-05 0.00459904694198129 -0.0327482586378685"
        rpy="0 0 0" />
      <mass
        value="0.243320868687054" />
      <inertia
        ixx="0.000326394043598111"
        ixy="3.96748456591628E-06"
        ixz="1.11931240417045E-08"
        iyy="0.000160203347703919"
        iyz="-1.08510273871772E-05"
        izz="0.000294334543426168" />
    </inertial>
    <visual>
      <origin
        xyz="0 0 0"
        rpy="0 0 0" />
      <geometry>
        <mesh
          filename="package://svenzva_description/meshes/link_6.STL" />
      </geometry>
      <material
        name="">
        <color
          rgba="0.298039215686275 0.298039215686275 0.298039215686275 1" />
      </material>
    </visual>
    <collision>
      <origin
        xyz="0 0 0"
        rpy="0 0 0" />
      <geometry>
        <mesh
          filename="package://svenzva_description/meshes/link_6.STL" />
      </geometry>
    </collision>
  </link>
  <joint
    name="joint_6"
    type="revolute">
    <origin
      xyz="-0.014463 0.080052 0.001425"
      rpy="1.5744 -1.5708 0" />
    <parent
      link="link_5" />
    <child
      link="link_6" />
    <axis
      xyz="0 0 -1" />
    <limit
      lower="-1.565"
      upper="1.565"
      effort="0"
      velocity="0" />
  </joint>
  <link
    name="finger_link_1">
    <inertial>
      <origin
        xyz="-0.00483282204262809 -0.00411403012500923 0.0206210772714723"
        rpy="0 0 0" />
      <mass
        value="0.0220307791071739" />
      <inertia
        ixx="9.08331950596468E-06"
        ixy="-2.05394082888464E-06"
        ixz="-2.23772944669454E-06"
        iyy="1.04239718244321E-05"
        iyz="-2.75990314800171E-06"
        izz="9.60841591398502E-06" />
    </inertial>
    <visual>
      <origin
        xyz="0 0 0"
        rpy="0 0 0" />
      <geometry>
        <mesh
          filename="package://svenzva_description/meshes/finger_link_1.STL" />
      </geometry>
      <material
        name="">
        <color
          rgba="0.898039215686275 0.917647058823529 0.929411764705882 1" />
      </material>
    </visual>
    <collision>
      <origin
        xyz="0 0 0"
        rpy="0 0 0" />
      <geometry>
        <mesh
          filename="package://svenzva_description/meshes/finger_link_1.STL" />
      </geometry>
    </collision>
  </link>
  <joint
    name="finger_joint_1"
    type="prismatic">
    <origin
      xyz="0 0 -0.052509"
      rpy="-3.1416 -1.8964E-18 3.1416" />
    <parent
      link="link_6" />
    <child
      link="finger_link_1" />
    <axis
      xyz="0 1 0" />
    <limit
      lower="0"
      upper="0.05"
      effort="0"
      velocity="0" />
  </joint>
  <link
    name="finger_joint_2">
    <inertial>
      <origin
        xyz="0.00483282233149502 0.00411402197005728 0.020621076918268"
        rpy="0 0 0" />
      <mass
        value="0.0220307791071739" />
      <inertia
        ixx="9.08331950596466E-06"
        ixy="-2.05394082888463E-06"
        ixz="2.23772944669453E-06"
        iyy="1.04239718244321E-05"
        iyz="2.75990314800169E-06"
        izz="9.60841591398501E-06" />
    </inertial>
    <visual>
      <origin
        xyz="0 0 0"
        rpy="0 0 0" />
      <geometry>
        <mesh
          filename="package://svenzva_description/meshes/finger_joint_2.STL" />
      </geometry>
      <material
        name="">
        <color
          rgba="0.898039215686275 0.917647058823529 0.929411764705882 1" />
      </material>
    </visual>
    <collision>
      <origin
        xyz="0 0 0"
        rpy="0 0 0" />
      <geometry>
        <mesh
          filename="package://svenzva_description/meshes/finger_joint_2.STL" />
      </geometry>
    </collision>
  </link>
  <joint
    name="finger_joint_2"
    type="prismatic">
    <origin
      xyz="0 0 -0.052509"
      rpy="-3.1416 -1.8964E-18 3.1416" />
    <parent
      link="link_6" />
    <child
      link="finger_joint_2" />
    <axis
      xyz="0 1 0" />
    <limit
      lower="-0.05"
      upper="0"
      effort="0"
      velocity="0" />
  </joint>

  <transmission name="joint_1_trans">
    <type>transmission_interface/SimpleTransmission</type>
    <joint name="joint_1">
      <hardwareInterface>EffortJointInterface</hardwareInterface>
    </joint>
    <actuator name="motor_1">
      <mechanicalReduction>4</mechanicalReduction>
      <hardwareInterface>EffortJointInterface</hardwareInterface>
    </actuator>
  </transmission>

<transmission name="joint_2_trans">
    <type>transmission_interface/SimpleTransmission</type>
    <joint name="joint_2">
      <hardwareInterface>EffortJointInterface</hardwareInterface>
    </joint>
  <actuator name="motor_2">
    <mechanicalReduction>6</mechanicalReduction>
    <hardwareInterface>EffortJointInterface</hardwareInterface>
  </actuator>
  </transmission>

<transmission name="joint_3_trans">
    <type>transmission_interface/SimpleTransmission</type>
    <joint name="joint_3">
      <hardwareInterface>EffortJointInterface</hardwareInterface>
    </joint>
  <actuator name="motor_3">
    <mechanicalReduction>6</mechanicalReduction>
    <hardwareInterface>EffortJointInterface</hardwareInterface>
  </actuator>
  </transmission>

<transmission name="joint_4_trans">
    <type>transmission_interface/SimpleTransmission</type>
    <joint name="joint_4">
      <hardwareInterface>EffortJointInterface</hardwareInterface>
    </joint>
  <actuator name="motor_4">
    <mechanicalReduction>1</mechanicalReduction>
    <hardwareInterface>EffortJointInterface</hardwareInterface>
  </actuator>
  </transmission>

<transmission name="joint_5_trans">
    <type>transmission_interface/SimpleTransmission</type>
    <joint name="joint_5">
      <hardwareInterface>EffortJointInterface</hardwareInterface>
    </joint>
  <actuator name="motor_5">
    <mechanicalReduction>4</mechanicalReduction>
    <hardwareInterface>EffortJointInterface</hardwareInterface>
  </actuator>
  </transmission>

<transmission name="joint_6_trans">
    <type>transmission_interface/SimpleTransmission</type>
    <joint name="joint_6">
      <hardwareInterface>EffortJointInterface</hardwareInterface>
    </joint>
  <actuator name="motor_6">
    <mechanicalReduction>1</mechanicalReduction>
    <hardwareInterface>EffortJointInterface</hardwareInterface>
  </actuator>
  </transmission>
</robot>
