<robot
  name="svenzva_arm">
  <link
    name="base_link">
    <inertial>
      <origin
        xyz="0.183063673786998 -0.0233084273828049 0.0180761484144128"
        rpy="0 0 0" />
      <mass
        value="0.0440503113116943" />
      <inertia
        ixx="1.2628682772721E-05"
        ixy="-1.40063677437599E-09"
        ixz="2.93618081359869E-11"
        iyy="7.82071238742822E-06"
        iyz="-3.61058153458016E-07"
        izz="1.04785928829056E-05" />
    </inertial>
    <visual>
      <origin
        xyz="0 0 0"
        rpy="0 0 0" />
      <geometry>
        <mesh
          filename="package://svenzva_description/meshes/base_link.STL" />
      </geometry>
      <material
        name="">
        <color
          rgba="0.792156862745098 0.819607843137255 0.933333333333333 1" />
      </material>
    </visual>
    <collision>
      <origin
        xyz="0 0 0"
        rpy="0 0 0" />
      <geometry>
        <mesh
          filename="package://svenzva_description/meshes/base_link.STL" />
      </geometry>
    </collision>
  </link>
  <link
    name="link_1">
    <inertial>
      <origin
        xyz="-0.00669571092499537 -0.0368461847487507 -0.00040412267076495"
        rpy="0 0 0" />
      <mass
        value="0.092508596891218" />
      <inertia
        ixx="5.00823152604E-05"
        ixy="-9.52391075519481E-07"
        ixz="-1.3835328811679E-08"
        iyy="2.49393046029841E-05"
        iyz="-1.11584591163509E-06"
        izz="4.10382693682704E-05" />
    </inertial>
    <visual>
      <origin
        xyz="0 0 0"
        rpy="0 0 0" />
      <geometry>
        <mesh
          filename="package://svenzva_description/meshes/link_1.STL" />
      </geometry>
      <material
        name="">
        <color
          rgba="0.792156862745098 0.819607843137255 0.933333333333333 1" />
      </material>
    </visual>
    <collision>
      <origin
        xyz="0 0 0"
        rpy="0 0 0" />
      <geometry>
        <mesh
          filename="package://svenzva_description/meshes/link_1.STL" />
      </geometry>
    </collision>
  </link>
  <joint
    name="joint_1"
    type="revolute">
    <limit effort="30" velocity="1.0" lower="-3.14" upper="3.14" />
    <origin
      xyz="0.183061688655131 -0.0119999999999999 0.0385000000000039"
      rpy="-1.5707963267949 -6.12303176911189E-17 -1.5707963267949" />
    <parent
      link="base_link" />
    <child
      link="link_1" />
    <axis
      xyz="0 -1 0" />
  </joint>
  <link
    name="link_2">
    <inertial>
      <origin
        xyz="0.169730547665212 0.000267822624829384 -2.70293399910748E-06"
        rpy="0 0 0" />
      <mass
        value="0.111498195075492" />
      <inertia
        ixx="4.89105220808729E-05"
        ixy="-2.08446061508749E-06"
        ixz="4.88591407223512E-09"
        iyy="0.000526174960648652"
        iyz="-4.1664980787648E-09"
        izz="0.000557293305490889" />
    </inertial>
    <visual>
      <origin
        xyz="0 0 0"
        rpy="0 0 0" />
      <geometry>
        <mesh
          filename="package://svenzva_description/meshes/link_2.STL" />
      </geometry>
      <material
        name="">
        <color
          rgba="0.792156862745098 0.819607843137255 0.933333333333333 1" />
      </material>
    </visual>
    <collision>
      <origin
        xyz="0 0 0"
        rpy="0 0 0" />
      <geometry>
        <mesh
          filename="package://svenzva_description/meshes/link_2.STL" />
      </geometry>
    </collision>
  </link>
  <joint
    name="joint_2"
    type="revolute">
    <limit effort="30" velocity="1.0" lower="-2.0" upper="2.0" />
    <origin
      xyz="-0.00699999999999987 -0.055 0"
      rpy="1.57079632679488 -1.38777878078116E-15 -1.57079632679488" />
    <parent
      link="link_1" />
    <child
      link="link_2" />
    <axis
      xyz="0 -1 0" />
  </joint>
  <link
    name="link_3">
    <inertial>
      <origin
        xyz="0.104634211418845 -0.000300467718270581 0.000313239201004826"
        rpy="0 0 0" />
      <mass
        value="0.0953320551486545" />
      <inertia
        ixx="3.26339299149426E-05"
        ixy="5.186789942043E-07"
        ixz="-1.37065559687992E-06"
        iyy="0.000153967149044495"
        iyz="7.05798957288694E-09"
        izz="0.000160335663631353" />
    </inertial>
    <visual>
      <origin
        xyz="0 0 0"
        rpy="0 0 0" />
      <geometry>
        <mesh
          filename="package://svenzva_description/meshes/link_3.STL" />
      </geometry>
      <material
        name="">
        <color
          rgba="0.792156862745098 0.819607843137255 0.933333333333333 1" />
      </material>
    </visual>
    <collision>
      <origin
        xyz="0 0 0"
        rpy="0 0 0" />
      <geometry>
        <mesh
          filename="package://svenzva_description/meshes/link_3.STL" />
      </geometry>
    </collision>
  </link>
  <joint
    name="joint_3"
    type="revolute">
    <limit effort="30" velocity="1.0" lower="-2.3" upper="2.3" />
    <origin
      xyz="0.2267 0 0"
      rpy="1.72604985859693E-14 -1.72604985859694E-14 -1.38777878078145E-15" />
    <parent
      link="link_2" />
    <child
      link="link_3" />
    <axis
      xyz="0 -1 0" />
  </joint>
  <link
    name="link_4">
    <inertial>
      <origin
        xyz="0.0934300576024393 -0.00177743629747678 0.000675027109716481"
        rpy="0 0 0" />
      <mass
        value="0.0669634671076673" />
      <inertia
        ixx="2.36196437720773E-05"
        ixy="2.79386743602087E-06"
        ixz="-1.42157135148173E-06"
        iyy="0.000111946472401709"
        iyz="4.1762270000039E-08"
        izz="0.000121123624755305" />
    </inertial>
    <visual>
      <origin
        xyz="0 0 0"
        rpy="0 0 0" />
      <geometry>
        <mesh
          filename="package://svenzva_description/meshes/link_4.STL" />
      </geometry>
      <material
        name="">
        <color
          rgba="0.792156862745098 0.819607843137255 0.933333333333333 1" />
      </material>
    </visual>
    <collision>
      <origin
        xyz="0 0 0"
        rpy="0 0 0" />
      <geometry>
        <mesh
          filename="package://svenzva_description/meshes/link_4.STL" />
      </geometry>
    </collision>
  </link>
  <joint
    name="joint_4"
    type="revolute">
    <limit effort="30" velocity="1.0" lower="-2.15" upper="2.15" />
    <origin
      xyz="0.1377 -0.000399999966000264 0"
      rpy="-1.5707963267949 -5.02171683388957E-18 -0.00827101619955667" />
    <parent
      link="link_3" />
    <child
      link="link_4" />
    <axis
      xyz="0 -1 0" />
  </joint>
  <link
    name="link_5">
    <inertial>
      <origin
        xyz="-0.055679 -0.00069857 -0.00085133"
        rpy="0 0 0" />
      <mass
        value="0.061656" />
      <inertia
        ixx="1.9463E-05"
        ixy="9.9886E-10"
        ixz="-9.737E-07"
        iyy="4.2362E-05"
        iyz="1.4317E-09"
        izz="4.3031E-05" />
    </inertial>
    <visual>
      <origin
        xyz="0 0 0"
        rpy="0 0 0" />
      <geometry>
        <mesh
          filename="package://svenzva_description/meshes/link_5.STL" />
      </geometry>
      <material
        name="">
        <color
          rgba="0.79216 0.81961 0.93333 1" />
      </material>
    </visual>
    <collision>
      <origin
        xyz="0 0 0"
        rpy="0 0 0" />
      <geometry>
        <mesh
          filename="package://svenzva_description/meshes/link_5.STL" />
      </geometry>
    </collision>
  </link>
  <joint
    name="joint_5"
    type="revolute">
    <limit effort="30" velocity="1.0" lower="-1.85" upper="1.85" />
    <origin
      xyz="0.1282 -0.00269999999999876 0"
      rpy="-1.5707963267949 -2.77729228503887E-15 -3.14159265358979" />
    <parent
      link="link_4" />
    <child
      link="link_5" />
    <axis
      xyz="0 -1 0" />
  </joint>
  <link
    name="link_6">
    <inertial>
      <origin
        xyz="0.00030317 5.9346E-05 0.037103"
        rpy="0 0 0" />
      <mass
        value="0.1101" />
      <inertia
        ixx="0.00013578"
        ixy="-3.5448E-08"
        ixz="-9.678E-06"
        iyy="9.8455E-05"
        iyz="-1.7723E-07"
        izz="6.6944E-05" />
    </inertial>
    <visual>
      <origin
        xyz="0 0 0"
        rpy="0 0 0" />
      <geometry>
        <mesh
          filename="package://svenzva_description/meshes/link_6.STL" />
      </geometry>
      <material
        name="">
        <color
          rgba="1 0.81569 0.40392 1" />
      </material>
    </visual>
    <collision>
      <origin
        xyz="0 0 0"
        rpy="0 0 0" />
      <geometry>
        <mesh
          filename="package://svenzva_description/meshes/link_6.STL" />
      </geometry>
    </collision>
  </link>
  <joint
    name="joint_6"
    type="revolute">
    <limit effort="30" velocity="1.0" lower="-6.0" upper="0.0" />
    <origin
      xyz="-0.0891078454541699 -0.000699989976996301 -0.0124999999999946"
      rpy="-1.5707963267949 -1.47451495458029E-15 1.5707963267949" />
    <parent
      link="link_5" />
    <child
      link="link_6" />
    <axis
      xyz="0 0 1" />
  </joint>
  <link
    name="ee_link">
  </link>
  
  <joint name="ee_joint" type="fixed">
    <parent link="link_6"/>
    <child link="ee_link"/>
    <origin xyz="0.015 0 0.15"/>
  </joint>
</robot>
