<robot
  name="svenzva_arm">
  <link
    name="base_link">
    <inertial>
      <origin
        xyz="-0.00749757584211239 -0.0260727382451595 -0.00880758053044964"
        rpy="1.57079 0 0" />
      <mass
        value="0.0440503098818098" />
      <inertia
        ixx="1.14006315895163E-05"
        ixy="-1.8259039687092E-07"
        ixz="-2.09674136409804E-06"
        iyy="1.04785922734721E-05"
        iyz="-3.11486239808121E-07"
        izz="9.04876308853534E-06" />
    </inertial>
    <visual>
      <origin
        xyz="0 0 0"
        rpy="1.57079 0 0" />
      <geometry>
        <mesh
          filename="package://svenzva_description/meshes/base_link.STL" />
      </geometry>
      <material
        name="">
        <color
          rgba="0.792156862745098 0.819607843137255 0.933333333333333 1" />
      </material>
    </visual>
    <collision>
      <origin
        xyz="0 0 0"
        rpy="0 0 0" />
      <geometry>
        <mesh
          filename="package://svenzva_description/meshes/base_link.STL" />
      </geometry>
    </collision>
  </link>
  <link
    name="link_1">
    <inertial>
      <origin
        xyz="-0.00848707217094159 0.038531727117887 0.00136052562690134"
        rpy="0 0 0" />
      <mass
        value="0.0905550798572669" />
      <inertia
        ixx="4.74993473537044E-05"
        ixy="9.42922548065486E-07"
        ixz="1.3330044417413E-08"
        iyy="2.40646830473331E-05"
        iyz="-1.09025900160599E-06"
        izz="3.87429894321101E-05" />
    </inertial>
    <visual>
      <origin
        xyz="0 0 0"
        rpy="0 0 0" />
      <geometry>
        <mesh
          filename="package://svenzva_description/meshes/link_1.STL" />
      </geometry>
      <material
        name="">
        <color
          rgba="0.792156862745098 0.819607843137255 0.933333333333333 1" />
      </material>
    </visual>
    <collision>
      <origin
        xyz="0 0 0"
        rpy="0 0 0" />
      <geometry>
        <mesh
          filename="package://svenzva_description/meshes/link_1.STL" />
      </geometry>
    </collision>
  </link>
  <joint
    name="joint_1"
    type="continuous">
    <origin
      xyz="0 0 0"
      rpy="1.57079 0.0 0.0" />
    <parent
      link="base_link" />
    <child
      link="link_1" />
    <axis
      xyz="0 -1 0" />
  </joint>
  <link
    name="link_2">
    <inertial>
      <origin
        xyz="-0.0550531951593829 0.167327506189909 0.000646310743751544"
        rpy="0 0 0" />
      <mass
        value="0.0990854582025164" />
      <inertia
        ixx="0.000405955357563133"
        ixy="0.000120035188119757"
        ixz="-5.78166971166389E-07"
        iyy="6.80763187629E-05"
        iyz="1.79491708729043E-06"
        izz="0.000431011754188035" />
    </inertial>
    <visual>
      <origin
        xyz="0 0 0"
        rpy="0 0 0" />
      <geometry>
        <mesh
          filename="package://svenzva_description/meshes/link_2.STL" />
      </geometry>
      <material
        name="">
        <color
          rgba="0.792156862745098 0.819607843137255 0.933333333333333 1" />
      </material>
    </visual>
    <collision>
      <origin
        xyz="0 0 0"
        rpy="0 0 0" />
      <geometry>
        <mesh
          filename="package://svenzva_description/meshes/link_2.STL" />
      </geometry>
    </collision>
  </link>
  <joint
    name="joint_2"
    type="continuous">
    <origin
      xyz="-0.00700000000002309 0.0549537554950766 0"
      rpy="0 0 -1.88424757676597" />
    <parent
      link="link_1" />
    <child
      link="link_2" />
    <axis
      xyz="0 0 -1" />
  </joint>
  <link
    name="link_3">
    <inertial>
      <origin
        xyz="0.000913356649708541 0.178150765648353 -0.00150867178307854"
        rpy="0 0 0" />
      <mass
        value="0.0987656165583022" />
      <inertia
        ixx="0.000433811813190151"
        ixy="-4.19089541940326E-07"
        ixz="4.25971952847169E-10"
        iyy="2.78117904165545E-05"
        iyz="9.04592294096768E-07"
        izz="0.000426224022242742" />
    </inertial>
    <visual>
      <origin
        xyz="0 0 0"
        rpy="0 0 0" />
      <geometry>
        <mesh
          filename="package://svenzva_description/meshes/link_3.STL" />
      </geometry>
      <material
        name="">
        <color
          rgba="0.792156862745098 0.819607843137255 0.933333333333333 1" />
      </material>
    </visual>
    <collision>
      <origin
        xyz="0 0 0"
        rpy="0 0 0" />
      <geometry>
        <mesh
          filename="package://svenzva_description/meshes/link_3.STL" />
      </geometry>
    </collision>
  </link>
  <joint
    name="link_3"
    type="continuous">
    <origin
      xyz="-0.07037 0.21525 0"
      rpy="0.3 -1.5708 0" />
    <parent
      link="link_2" />
    <child
      link="link_3" />
    <axis
      xyz="-1 0 0" />
  </joint>
  <link
    name="link_4">
    <inertial>
      <origin
        xyz="-0.00204498879952503 0.141369132160178 -2.06189305049231E-05"
        rpy="0 0 0" />
      <mass
        value="0.0667180708029316" />
      <inertia
        ixx="0.000240059238972242"
        ixy="-3.12955865012509E-07"
        ixz="6.19105026644054E-11"
        iyy="1.62253539008704E-05"
        iyz="-1.30465141365934E-07"
        izz="0.000237210594341217" />
    </inertial>
    <visual>
      <origin
        xyz="0 0 0"
        rpy="0 0 0" />
      <geometry>
        <mesh
          filename="package://svenzva_description/meshes/link_4.STL" />
      </geometry>
      <material
        name="">
        <color
          rgba="0.792156862745098 0.819607843137255 0.933333333333333 1" />
      </material>
    </visual>
    <collision>
      <origin
        xyz="0 0 0"
        rpy="0 0 0" />
      <geometry>
        <mesh
          filename="package://svenzva_description/meshes/link_4.STL" />
      </geometry>
    </collision>
  </link>
  <joint
    name="joint_4"
    type="continuous">
    <origin
      xyz="0.00094769 0.228 0"
      rpy="0 -1.5708 0" />
    <parent
      link="link_3" />
    <child
      link="link_4" />
    <axis
      xyz="1 0 0" />
  </joint>
  <link
    name="link_5">
    <inertial>
      <origin
        xyz="-0.000567372158605861 -0.010273892962458 0.0475789309071154"
        rpy="0 0 0" />
      <mass
        value="0.0487770287268765" />
      <inertia
        ixx="1.83421961142492E-05"
        ixy="1.58589924901683E-07"
        ixz="-7.40441313764976E-07"
        iyy="1.42403806819404E-05"
        iyz="1.46093223787699E-06"
        izz="1.2742998301539E-05" />
    </inertial>
    <visual>
      <origin
        xyz="0 0 0"
        rpy="0 0 0" />
      <geometry>
        <mesh
          filename="package://svenzva_description/meshes/link_5.STL" />
      </geometry>
      <material
        name="">
        <color
          rgba="0.792156862745098 0.819607843137255 0.933333333333333 1" />
      </material>
    </visual>
    <collision>
      <origin
        xyz="0 0 0"
        rpy="0 0 0" />
      <geometry>
        <mesh
          filename="package://svenzva_description/meshes/link_5.STL" />
      </geometry>
    </collision>
  </link>
  <joint
    name="joint_5"
    type="continuous">
    <origin
      xyz="-0.002 0.1909 0"
      rpy="0 0 0" />
    <parent
      link="link_4" />
    <child
      link="link_5" />
    <axis
      xyz="-1 0 0" />
  </joint>
  <link
    name="link_6">
    <inertial>
      <origin
        xyz="6.5893157041863E-09 -0.0010414957680589 -1.12558772302762E-08"
        rpy="0 0 0" />
      <mass
        value="0.00316138019909441" />
      <inertia
        ixx="2.52290784110039E-07"
        ixy="1.27363946384305E-13"
        ixz="-1.82311715301311E-08"
        iyy="6.22416180563718E-07"
        iyz="3.35195652061741E-15"
        izz="4.34712903094774E-07" />
    </inertial>
    <visual>
      <origin
        xyz="0 0 0"
        rpy="0 0 0" />
      <geometry>
        <mesh
          filename="package://svenzva_description/meshes/link_6.STL" />
      </geometry>
      <material
        name="">
        <color
          rgba="0.792156862745098 0.819607843137255 0.933333333333333 1" />
      </material>
    </visual>
    <collision>
      <origin
        xyz="0 0 0"
        rpy="0 0 0" />
      <geometry>
        <mesh
          filename="package://svenzva_description/meshes/link_6.STL" />
      </geometry>
    </collision>
  </link>
  <joint
    name="joint_6"
    type="continuous">
    <origin
      xyz="-0.00025 0 0.0763"
      rpy="1.5708 0 1.5478" />
    <parent
      link="link_5" />
    <child
      link="link_6" />
    <axis
      xyz="0 1 0" />
  </joint>
  <link
    name="link7">
    <inertial>
      <origin
        xyz="-0.0203622077205162 -0.0156221581500527 -0.000703554666599548"
        rpy="0 0 0" />
      <mass
        value="0.0507605721594301" />
      <inertia
        ixx="4.63823726602191E-05"
        ixy="1.14253480839073E-06"
        ixz="8.86564925864172E-08"
        iyy="1.088775582314E-05"
        iyz="4.92685310342354E-06"
        izz="4.43541098679823E-05" />
    </inertial>
    <visual>
      <origin
        xyz="0 0 0"
        rpy="0 0 0" />
      <geometry>
        <mesh
          filename="package://svenzva_description/meshes/link7.STL" />
      </geometry>
      <material
        name="">
        <color
          rgba="0.792156862745098 0.819607843137255 0.933333333333333 1" />
      </material>
    </visual>
    <collision>
      <origin
        xyz="0 0 0"
        rpy="0 0 0" />
      <geometry>
        <mesh
          filename="package://svenzva_description/meshes/link7.STL" />
      </geometry>
    </collision>
  </link>
  <joint
    name="joint7"
    type="fixed">
    <origin
      xyz="0 0.0522460954380538 0"
      rpy="8.45519530120473E-15 1.47215648980489 8.45519530120475E-15" />
    <parent
      link="link_6" />
    <child
      link="link7" />
    <axis
      xyz="0 0 0" />
  </joint>
  <link
    name="link8">
    <inertial>
      <origin
        xyz="0.0064297437620191 -0.0193217305363396 0.000703554666948825"
        rpy="0 0 0" />
      <mass
        value="0.0507605721592847" />
      <inertia
        ixx="1.34526011562136E-05"
        ixy="-9.24798022848996E-06"
        ixz="4.80545029688283E-06"
        iyy="4.38292588729498E-05"
        iyz="1.08998710861812E-06"
        izz="4.43658414139048E-05" />
    </inertial>
    <visual>
      <origin
        xyz="0 0 0"
        rpy="0 0 0" />
      <geometry>
        <mesh
          filename="package://svenzva_description/meshes/link8.STL" />
      </geometry>
      <material
        name="">
        <color
          rgba="1 1 1 1" />
      </material>
    </visual>
    <collision>
      <origin
        xyz="0 0 0"
        rpy="0 0 0" />
      <geometry>
        <mesh
          filename="package://svenzva_description/meshes/link8.STL" />
      </geometry>
    </collision>
  </link>
  <joint
    name="joint8"
    type="fixed">
    <origin
      xyz="0 0.0382618235839969 0"
      rpy="1.67234778664861 0.239641933396132 -1.54661411305579" />
    <parent
      link="link_6" />
    <child
      link="link8" />
    <axis
      xyz="0 0 0" />
  </joint>
</robot>
