<robot
  name="svenzva_arm">
  <link
    name="base_link">
    <inertial>
      <origin
        xyz="0.18306367413687 -0.0233084276298693 0.0180761484144128"
        rpy="0 0 0" />
      <mass
        value="0.0440503113116943" />
      <inertia
        ixx="1.26286826095278E-05"
        ixy="-1.40068407294731E-09"
        ixz="2.90163117689784E-11"
        iyy="7.82071230441501E-06"
        iyz="-3.61057953014732E-07"
        izz="1.04785926366992E-05" />
    </inertial>
    <visual>
      <origin
        xyz="0 0 0"
        rpy="0 0 0" />
      <geometry>
        <mesh
          filename="package://svenzva_description/meshes/base_link.STL" />
      </geometry>
      <material
        name="">
        <color
          rgba="0.792156862745098 0.819607843137255 0.933333333333333 1" />
      </material>
    </visual>
    <collision>
      <origin
        xyz="0 0 0"
        rpy="0 0 0" />
      <geometry>
        <mesh
          filename="package://svenzva_description/meshes/base_link.STL" />
      </geometry>
    </collision>
  </link>
  <link
    name="link_1">
    <inertial>
      <origin
        xyz="-0.00669571090553394 0.0388461846451639 0.000404122685555286"
        rpy="0 0 0" />
      <mass
        value="0.0925085972682552" />
      <inertia
        ixx="5.00823155961961E-05"
        ixy="9.52391117758938E-07"
        ixz="1.38353181525861E-08"
        iyy="2.49393047672637E-05"
        iyz="-1.11584585407224E-06"
        izz="4.10382695934873E-05" />
    </inertial>
    <visual>
      <origin
        xyz="0 0 0"
        rpy="0 0 0" />
      <geometry>
        <mesh
          filename="package://svenzva_description/meshes/link_1.STL" />
      </geometry>
      <material
        name="">
        <color
          rgba="0.792156862745098 0.819607843137255 0.933333333333333 1" />
      </material>
    </visual>
    <collision>
      <origin
        xyz="0 0 0"
        rpy="0 0 0" />
      <geometry>
        <mesh
          filename="package://svenzva_description/meshes/link_1.STL" />
      </geometry>
    </collision>
  </link>
  <joint
    name="joint_1"
    type="continuous">
    <origin
      xyz="0.183061688655131 -0.012 0.036500000000004"
      rpy="1.5707963267949 -6.12285515858645E-17 -1.5632010942264" />
    <parent
      link="base_link" />
    <child
      link="link_1" />
    <axis
      xyz="0 1 0" />
  </joint>
  <link
    name="link_2">
    <inertial>
      <origin
        xyz="0.169730547677992 -0.000267822600205109 2.70292759354911E-06"
        rpy="0 0 0" />
      <mass
        value="0.111498195078862" />
      <inertia
        ixx="4.89105220783554E-05"
        ixy="2.08446050442835E-06"
        ixz="-4.88588295210281E-09"
        iyy="0.000526174960723493"
        iyz="-4.16648472352863E-09"
        izz="0.000557293305563762" />
    </inertial>
    <visual>
      <origin
        xyz="0 0 0"
        rpy="0 0 0" />
      <geometry>
        <mesh
          filename="package://svenzva_description/meshes/link_2.STL" />
      </geometry>
      <material
        name="">
        <color
          rgba="0.792156862745098 0.819607843137255 0.933333333333333 1" />
      </material>
    </visual>
    <collision>
      <origin
        xyz="0 0 0"
        rpy="0 0 0" />
      <geometry>
        <mesh
          filename="package://svenzva_description/meshes/link_2.STL" />
      </geometry>
    </collision>
  </link>
  <joint
    name="joint_2"
    type="continuous">
    <origin
      xyz="-0.007 0.057 0"
      rpy="1.5708 -1.3131E-15 1.5993" />
    <parent
      link="link_1" />
    <child
      link="link_2" />
    <axis
      xyz="0 -1 0" />
  </joint>
  <link
    name="link_3">
    <inertial>
      <origin
        xyz="0.104641483307686 -0.0269135497501998 -0.00380446608306266"
        rpy="0 0 0" />
      <mass
        value="0.095277105355898" />
      <inertia
        ixx="3.29577050210334E-05"
        ixy="5.18470840609121E-07"
        ixz="5.13705244462317E-06"
        iyy="0.000154303544092084"
        iyz="-2.3943529166925E-08"
        izz="0.000160305190604025" />
    </inertial>
    <visual>
      <origin
        xyz="0 0 0"
        rpy="0 0 0" />
      <geometry>
        <mesh
          filename="package://svenzva_description/meshes/link_3.STL" />
      </geometry>
      <material
        name="">
        <color
          rgba="0.792156862745098 0.819607843137255 0.933333333333333 1" />
      </material>
    </visual>
    <collision>
      <origin
        xyz="0 0 0"
        rpy="0 0 0" />
      <geometry>
        <mesh
          filename="package://svenzva_description/meshes/link_3.STL" />
      </geometry>
    </collision>
  </link>
  <joint
    name="joint_3"
    type="continuous">
    <origin
      xyz="0.226700000000002 -0.0266129086637006 0"
      rpy="3.14159265358979 0.0162072294682094 -1.40791300798038E-15" />
    <parent
      link="link_2" />
    <child
      link="link_3" />
    <axis
      xyz="0 1 0" />
  </joint>
  <link
    name="link_4">
    <inertial>
      <origin
        xyz="0.0930650436809971 0.00334712751247027 0.00491549180258602"
        rpy="0 0 0" />
      <mass
        value="0.0630903380817815" />
      <inertia
        ixx="2.22616217444818E-05"
        ixy="2.7626528511705E-06"
        ixz="-7.50803987277433E-06"
        iyy="0.00011058046285098"
        iyz="2.63341119772381E-07"
        izz="0.000119134391315269" />
    </inertial>
    <visual>
      <origin
        xyz="0 0 0"
        rpy="0 0 0" />
      <geometry>
        <mesh
          filename="package://svenzva_description/meshes/link_4.STL" />
      </geometry>
      <material
        name="">
        <color
          rgba="0.792156862745098 0.819607843137255 0.933333333333333 1" />
      </material>
    </visual>
    <collision>
      <origin
        xyz="0 0 0"
        rpy="0 0 0" />
      <geometry>
        <mesh
          filename="package://svenzva_description/meshes/link_4.STL" />
      </geometry>
    </collision>
  </link>
  <joint
    name="joint_4"
    type="continuous">
    <origin
      xyz="0.137700000000002 -0.0270129086636999 0"
      rpy="-1.5707963267949 -9.0205620750794E-16 -0.000965169435000781" />
    <parent
      link="link_3" />
    <child
      link="link_4" />
    <axis
      xyz="0 1 0" />
  </joint>
  <link
    name="link_5">
    <inertial>
      <origin
        xyz="-0.0510929189416032 -0.007500678328939 0.00565598618945374"
        rpy="0 0 0" />
      <mass
        value="0.0564481780820506" />
      <inertia
        ixx="1.76538077615808E-05"
        ixy="-1.46152633641026E-07"
        ixz="2.64184773175406E-06"
        iyy="3.5301263455787E-05"
        iyz="2.44903631073847E-08"
        izz="3.47267638978701E-05" />
    </inertial>
    <visual>
      <origin
        xyz="0 0 0"
        rpy="0 0 0" />
      <geometry>
        <mesh
          filename="package://svenzva_description/meshes/link_5.STL" />
      </geometry>
      <material
        name="">
        <color
          rgba="0.792156862745098 0.819607843137255 0.933333333333333 1" />
      </material>
    </visual>
    <collision>
      <origin
        xyz="0 0 0"
        rpy="0 0 0" />
      <geometry>
        <mesh
          filename="package://svenzva_description/meshes/link_5.STL" />
      </geometry>
    </collision>
  </link>
  <joint
    name="joint_5"
    type="continuous">
    <origin
      xyz="0.1282 0.00249999999999978 0"
      rpy="-1.5707963267949 4.61393076522931E-15 3.13849286930343" />
    <parent
      link="link_4" />
    <child
      link="link_5" />
    <axis
      xyz="0 -1 0" />
  </joint>
  <link
    name="link_6">
    <inertial>
      <origin
        xyz="-0.000997723473252839 3.27329374569807E-05 0.0273503511100585"
        rpy="0 0 0" />
      <mass
        value="0.0901281281958769" />
      <inertia
        ixx="5.1617818672763E-05"
        ixy="-4.21990305426345E-07"
        ixz="2.63694492760559E-07"
        iyy="2.70403490435013E-05"
        iyz="3.28212546738033E-08"
        izz="4.376014884586E-05" />
    </inertial>
    <visual>
      <origin
        xyz="0 0 0"
        rpy="0 0 0" />
      <geometry>
        <mesh
          filename="package://svenzva_description/meshes/link_6.STL" />
      </geometry>
      <material
        name="">
        <color
          rgba="1 0.815686274509804 0.403921568627451 1" />
      </material>
    </visual>
    <collision>
      <origin
        xyz="0 0 0"
        rpy="0 0 0" />
      <geometry>
        <mesh
          filename="package://svenzva_description/meshes/link_6.STL" />
      </geometry>
    </collision>
  </link>
  <joint
    name="joint_6"
    type="continuous">
    <origin
      xyz="-0.0838128178357174 -0.00757500000000258 -0.00400000000009831"
      rpy="1.57079632678785 -1.56490357222949 -1.57079632678785" />
    <parent
      link="link_5" />
    <child
      link="link_6" />
    <axis
      xyz="0 0 1" />
  </joint>
  <link
    name="link_finger_1">
    <inertial>
      <origin
        xyz="-0.00964294537748545 0.00759892626932133 0.0159294086406723"
        rpy="0 0 0" />
      <mass
        value="0.0100194667897186" />
      <inertia
        ixx="3.08188650306691E-06"
        ixy="2.01580181742404E-07"
        ixz="-2.14539420423337E-06"
        iyy="1.30321517472818E-05"
        iyz="1.14165617181553E-08"
        izz="1.15971173056784E-05" />
    </inertial>
    <visual>
      <origin
        xyz="0 0 0"
        rpy="0 0 0" />
      <geometry>
        <mesh
          filename="package://svenzva_description/meshes/link_finger_1.STL" />
      </geometry>
      <material
        name="">
        <color
          rgba="1 1 1 1" />
      </material>
    </visual>
    <collision>
      <origin
        xyz="0 0 0"
        rpy="0 0 0" />
      <geometry>
        <mesh
          filename="package://svenzva_description/meshes/link_finger_1.STL" />
      </geometry>
    </collision>
  </link>
  <joint
    name="finger_1"
    type="fixed">
    <origin
      xyz="0.0222737654014398 0.0365533597460683 0.0727446167971825"
      rpy="-1.5707963267949 1.33127052458092 1.55441469771021" />
    <parent
      link="link_6" />
    <child
      link="link_finger_1" />
    <axis
      xyz="0 0 0" />
  </joint>
  <link
    name="link_finger_2">
    <inertial>
      <origin
        xyz="-0.00972976837534922 0.0079524364327318 0.0276595789410328"
        rpy="0 0 0" />
      <mass
        value="0.0100194667897082" />
      <inertia
        ixx="3.08188650289703E-06"
        ixy="2.01580181742893E-07"
        ixz="2.14539420294894E-06"
        iyy="1.30321517471009E-05"
        iyz="-1.14165618233301E-08"
        izz="1.15971173056673E-05" />
    </inertial>
    <visual>
      <origin
        xyz="0 0 0"
        rpy="0 0 0" />
      <geometry>
        <mesh
          filename="package://svenzva_description/meshes/link_finger_2.STL" />
      </geometry>
      <material
        name="">
        <color
          rgba="1 1 1 1" />
      </material>
    </visual>
    <collision>
      <origin
        xyz="0 0 0"
        rpy="0 0 0" />
      <geometry>
        <mesh
          filename="package://svenzva_description/meshes/link_finger_2.STL" />
      </geometry>
    </collision>
  </link>
  <joint
    name="finger_2"
    type="fixed">
    <origin
      xyz="-0.0225240000000001 -0.0368716233284919 0.0727685295284096"
      rpy="-1.57079632679489 1.32996070258273 -1.58717795587957" />
    <parent
      link="link_6" />
    <child
      link="link_finger_2" />
    <axis
      xyz="0 0 0" />
  </joint>
</robot>
