<robot
  name="revel">
  <link
    name="base_link">
    <inertial>
      <origin
        xyz="-0.0023730528889142 -0.00502093782805647 0.0237603120106106"
        rpy="0 0 0" />
      <mass
        value="0.774961748747901" />
    <inertia
        ixx="0.00201866828203214"
        ixy="-1.40341741820078E-05"
        ixz="5.0229742322277E-06"
        iyy="0.00196560351814595"
        iyz="2.49903357518308E-05"
        izz="0.00317820785242523" />
    </inertial>

    <visual>
      <origin
        xyz="0 0 0"
        rpy="0 0 0" />
      <geometry>
        <mesh
          filename="package://4_25_urdf6/meshes/base_link.STL" />
      </geometry>
      <material
        name="">
        <color
          rgba="0.792156862745098 0.819607843137255 0.933333333333333 1" />
      </material>
    </visual>
    <collision>
      <origin
        xyz="0 0 0"
        rpy="0 0 0" />
      <geometry>
        <mesh
          filename="package://4_25_urdf6/meshes/base_link.STL" />
      </geometry>
    </collision>
  </link>
  <link
    name="link_1">
    <inertial>
      <origin
        xyz="-1.5879447236338E-05 -0.00709916492149038 0.0638496557944277"
        rpy="0 0 0" />
      <mass
        value="0.29849024" />
      <inertia
        ixx="0.000632049493639531"
        ixy="4.97008463061611E-09"
        ixz="-3.22891235511891E-07"
        iyy="0.000568859462204089"
        iyz="5.38876127197549E-05"
        izz="0.000140153748296134" />
    </inertial>
    <visual>
      <origin
        xyz="0 0 0"
        rpy="0 0 0" />
      <geometry>
        <mesh
          filename="package://4_25_urdf6/meshes/link_1.STL" />
      </geometry>
      <material
        name="">
        <color
          rgba="0.898039215686275 0.917647058823529 0.929411764705882 1" />
      </material>
    </visual>
    <collision>
      <origin
        xyz="0 0 0"
        rpy="0 0 0" />
      <geometry>
        <mesh
          filename="package://4_25_urdf6/meshes/link_1.STL" />
      </geometry>
    </collision>
  </link>
  <joint
    name="joint_1"
    type="revolute">
    <origin
      xyz="0 0 0.06485"
      rpy="0 0 -1.5708" />
    <parent
      link="base_link" />
    <child
      link="link_1" />
    <axis
      xyz="0 0 -1" />
    <limit
      lower="-3.14"
      upper="3.14"
      effort="30"
      velocity="1.0" />
  </joint>
  <link
    name="link_2">
    <inertial>
      <origin
        xyz="9.60103803698233E-07 0.107533810370169 0.00620995831245331"
        rpy="0 0 0" />
      <mass
        value="0.327742070931929" />
      <inertia
        ixx="0.0025813073519799"
        ixy="-6.51323777188777E-09"
        ixz="-4.69675138347534E-09"
        iyy="0.000164682426511103"
        iyz="0.000191782548652168"
        izz="0.00252156627190461" />
    </inertial>
    <visual>
      <origin
        xyz="0 0 0"
        rpy="0 0 0" />
      <geometry>
        <mesh
          filename="package://4_25_urdf6/meshes/link_2.STL" />
      </geometry>
      <material
        name="">
        <color
          rgba="0.898039215686275 0.917647058823529 0.929411764705882 1" />
      </material>
    </visual>
    <collision>
      <origin
        xyz="0 0 0"
        rpy="0 0 0" />
      <geometry>
        <mesh
          filename="package://4_25_urdf6/meshes/link_2.STL" />
      </geometry>
    </collision>
  </link>
  <joint
    name="joint_2"
    type="revolute">
    <origin
      xyz="0 -0.015113 0.1155"
      rpy="1.5708 0 4.3282E-16" />
    <parent
      link="link_1" />
    <child
      link="link_2" />
    <axis
      xyz="0 0 -1" />
    <limit
      lower="-2"
      upper="2"
      effort="30"
      velocity="1.0" />
  </joint>
  <link
    name="link_3">
    <inertial>
      <origin
        xyz="-0.00271183900274356 0.0610091301092551 0.00559400264418311"
        rpy="0 0 0" />
      <mass
        value="0.280463750144268" />
      <inertia
        ixx="0.000852332127205566"
        ixy="3.05617676769096E-05"
        ixz="-4.39892054392222E-06"
        iyy="0.000157229318787424"
        iyz="0.000101462240345892"
        izz="0.000881573507420737" />
    </inertial>
    <visual>
      <origin
        xyz="0 0 0"
        rpy="0 0 0" />
      <geometry>
        <mesh
          filename="package://4_25_urdf6/meshes/link_3.STL" />
      </geometry>
      <material
        name="">
        <color
          rgba="0.898039215686275 0.917647058823529 0.929411764705882 1" />
      </material>
    </visual>
    <collision>
      <origin
        xyz="0 0 0"
        rpy="0 0 0" />
      <geometry>
        <mesh
          filename="package://4_25_urdf6/meshes/link_3.STL" />
      </geometry>
    </collision>
  </link>
  <joint
    name="joint_3"
    type="revolute">
    <origin
      xyz="0 0.2277 -0.009226"
      rpy="3.1416 -1.5345E-16 3.1416" />
    <parent
      link="link_2" />
    <child
      link="link_3" />
    <axis
      xyz="0 0 -1" />
    <limit
      lower="-2"
      upper="2"
      effort="30"
      velocity="1.0" />
  </joint>
  <link
    name="link_4">
    <inertial>
      <origin
        xyz="0.00313257969328566 0.0815755631836339 -0.00624759833233165"
        rpy="0 0 0" />
      <mass
        value="0.246221245377158" />
      <inertia
        ixx="0.000770915696557281"
        ixy="-2.42312978538393E-05"
        ixz="-3.37806113888413E-06"
        iyy="0.000179701091560925"
        iyz="-8.95366432461733E-05"
        izz="0.000734605505878042" />

    </inertial>
    <visual>
      <origin
        xyz="0 0 0"
        rpy="0 0 0" />
      <geometry>
        <mesh
          filename="package://4_25_urdf6/meshes/link_4.STL" />
      </geometry>
      <material
        name="">
        <color
          rgba="0.898039215686275 0.917647058823529 0.929411764705882 1" />
      </material>
    </visual>
    <collision>
      <origin
        xyz="0 0 0"
        rpy="0 0 0" />
      <geometry>
        <mesh
          filename="package://4_25_urdf6/meshes/link_4.STL" />
      </geometry>
    </collision>
  </link>
  <joint
    name="joint_4"
    type="revolute">
    <origin
      xyz="-0.00165 0.1377 -0.000388"
      rpy="0 1.5708 0" />
    <parent
      link="link_3" />
    <child
      link="link_4" />
    <axis
      xyz="0 0 1" />
    <limit
      lower="-1.7"
      upper="1.7"
      effort="30"
      velocity="1.0" />
  </joint>
  <link
    name="link_5">
    <inertial>
      <origin
        xyz="0.000198872480250657 0.0318752691244907 0.00773763240050632"
        rpy="0 0 0" />
      <mass
        value="0.163854288137822" />
      <inertia
        ixx="0.000177331781147381"
        ixy="1.29308489343752E-07"
        ixz="1.97866268691943E-07"
        iyy="0.000129668345614458"
        iyz="3.29586592910205E-05"
        izz="0.000140389798299154" />
    </inertial>
    <visual>
      <origin
        xyz="0 0 0"
        rpy="0 0 0" />
      <geometry>
        <mesh
          filename="package://4_25_urdf6/meshes/link_5.STL" />
      </geometry>
      <material
        name="">
        <color
          rgba="0.898039215686275 0.917647058823529 0.929411764705882 1" />
      </material>
    </visual>
    <collision>
      <origin
        xyz="0 0 0"
        rpy="0 0 0" />
      <geometry>
        <mesh
          filename="package://4_25_urdf6/meshes/link_5.STL" />
      </geometry>
    </collision>
  </link>
  <joint
    name="joint_5"
    type="revolute">
    <origin
      xyz="0.00165 0.1504 -0.0015875"
      rpy="0 1.5708 0" />
    <parent
      link="link_4" />
    <child
      link="link_5" />
    <axis
      xyz="0 0 -1" />
    <limit
      lower="-1.7"
      upper="1.7"
      effort="30"
      velocity="1.0" />
  </joint>
  <link
    name="link_6">
    <inertial>
      <origin
        xyz="0.00579554535449743 -1.99117701069566E-05 -0.0330401015812523"
        rpy="0 0 0" />
      <mass
        value="0.251621037329208" />
       <inertia
        ixx="0.000169268330339636"
        ixy="-4.03302147710687E-06"
        ixz="-1.34528597558469E-05"
        iyy="0.000338937907673271"
        iyz="1.42530899950337E-08"
        izz="0.000302776889549252" /> 
    </inertial>
    <visual>
      <origin
        xyz="0 0 0"
        rpy="0 0 0" />
      <geometry>
        <mesh
          filename="package://4_25_urdf6/meshes/link_6.STL" />
      </geometry>
      <material
        name="">
        <color
          rgba="0.792156862745098 0.819607843137255 0.933333333333333 1" />
      </material>
    </visual>
    <collision>
      <origin
        xyz="0 0 0"
        rpy="0 0 0" />
      <geometry>
        <mesh
          filename="package://4_25_urdf6/meshes/link_6.STL" />
      </geometry>
    </collision>
  </link>
  <joint
    name="joint_6"
    type="revolute">
    <origin
      xyz="-0.01475 0.08 0.001425"
      rpy="1.5708 3.14159 0" />
    <parent
      link="link_5" />
    <child
      link="link_6" />
    <axis
      xyz="0 0 -1" />
    <limit
      lower="0"
      upper="6.0"
      effort="30"
      velocity="1.0" />
  </joint>
  <link
    name="link_7">
    <inertial>
      <origin
        xyz="-4.33014013534461E-10 4.1616174568937E-10 0.022087275711041"
        rpy="0 0 0" />
      <mass
        value="0.0478690095652066" />
       <inertia
        ixx="2.65185843160199E-05"
        ixy="6.98858074467049E-06"
        ixz="-4.32758524413134E-20"
        iyy="2.31848725352889E-05"
        iyz="2.45012774391977E-20"
        izz="2.8122859649185E-05" />
    </inertial>  
    <visual>
      <origin
        xyz="0 0 0"
        rpy="0 0 0" />
      <geometry>
        <mesh
          filename="package://4_25_urdf6/meshes/link_finger_1.STL" />
      </geometry>
      <material
        name="">
        <color
          rgba="0.752941176470588 0.752941176470588 0.752941176470588 1" />
      </material>
    </visual>
    <collision>
      <origin
        xyz="0 0 0"
        rpy="0 0 0" />
      <geometry>
        <mesh
          filename="package://4_25_urdf6/meshes/link_finger_1.STL" />
      </geometry>
    </collision>
  </link>
  <joint
    name="joint_7"
    type="prismatic">
    <origin
      xyz="0 0 -0.052509"
      rpy="3.1416 3.0358E-17 3.1416" />
    <parent
      link="link_6" />
    <child
      link="link_7" />
    <axis
      xyz="-1 0 0" />
    <limit
      lower="-0.05"
      upper="0.05"
      effort="30"
      velocity="1.0" />
  </joint>

  <link name="ee_link"> </link>
  <joint name="ee_joint" type="fixed">
    <parent link="link_6"/>
    <child link="ee_link"/>
    <origin xyz="0 0 0.0"/>
  </joint>

</robot>
